Workbook

Sheet Construction
A1: Account / Project Details | B1: Description | D1: Notes
A2: Account Name | D2: Match Google Account Name
A3: Legal Account Name | D3: Legal name of the facility (only needed with A&E)
A4: Account Address | D4: Match Address from Google
A5: Project Name | D5: Match Project Description from CD Drawings
A6: Room Type
A7: Construction Type
A8: RFI Due Date
A9: Bid Due Date
A11: Construction Details | B11: Description | D11: Notes
A12: Takeoff or Hard Bids?
A13: Major Exclusions?
A14: Proposed Phasing?
A15: Below Slab Accessible?
A16: Any Floors Above?
A17: Deck Height
A18: Ceiling Height
A19: Nurse Call Vendor
A20: Mechanical Controls Vendor
A21: Preferred Data Vendor
A22: Preferred MEP Vendors
A23: Preferred Sprinkler Vendor
... A32: Plumbing / Med-Gas Scope of Work
A34: Quote Details | B34: Description | D34: Notes
A35: Pricing Display
A36: Quoting Format
A37: Deposit?
A38: Design Contingency?
A39: Construction Contingency?
A41: Account Contact Details | B41: Name | C41: Phone # | D41: Email Address
A42: Project Champion
A43: Project Manager
A44: Clinical Leader
A45: Invoicing
A46: Facilities
A47: ICRA
A48: Safety
A49: Equipment Vendor
A50: Physicist
A51: Architect
...

Sheet Install Pricelist
A1: Ondal SAP Description | B1: Price (US$) | C1: 2022 Pricing | D1: 2025 Pricing
A2: Install MediBoom Standard, XL, XXL | B2: 2425 | C2: =B2*1.05 -> 2546.25 | D2: =C2*1.1 -> 2800.875
A3: Install Motorized MediBoom Stand.,XL,XXL | B3: 2920 | C3: =B3*1.05 -> 3066 | D3: =C3*1.1 -> 3372.6
A4: Install CEMOR Large Monitor Carrier | B4: 2920 | C4: =B4*1.05 -> 3066 | D4: =C4*1.1 -> 3372.6
A5: Install MediSpace | B5: 2135 | C5: =B5*1.05 -> 2241.75 | D5: =C5*1.1 -> 2465.925
A6: Install SpacePoint System | B6: 1815 | C6: =B6*1.05 -> 1905.75 | D6: =C6*1.1 -> 2096.325
A7: Install Valia Single Arm Lighting System | B7: 1695 | C7: =B7*1.05 -> 1779.75 | D7: =C7*1.1 -> 1957.725
A8: Install Valia Single Arm Monitor System | B8: 1395 | C8: =B8*1.05 -> 1464.75 | D8: =C8*1.1 -> 1611.225
A9: Install Valia Dual Arm Lighting System | B9: 2235 | C9: =B9*1.05 -> 2346.75 | D9: =C9*1.1 -> 2581.425
A10: Install Valia Dual Arm Lighting/Monitor | B10: 2045 | C10: =B10*1.05 -> 2147.25 | D10: =C10*1.1 -> 2361.975
A11: Install Valia Triple Arm Lighting/Monito | B11: 2925 | C11: =B11*1.05 -> 3071.25 | D11: =C11*1.1 -> 3378.375
A12: Remove Existing Equip, Anes, Perf Boom | B12: 995 | C12: =B12*1.05 -> 1044.75 | D12: =C12*1.1 -> 1149.225
A13: Remove Motorized Equip,Anes,Perf Boom | B13: 1095 | C13: =B13*1.05 -> 1149.75 | D13: =C13*1.1 -> 1264.725
... A29: MB Standard, XL,XXL-Extended Warr.-1 yr | B29: 1395 | C29: =B29*1.05 -> 1464.75 | D29: =C29*1.1 -> 1611.225
A30: MB Standard, XL,XXL-Extended Warr.-2 yr | B30: =B29*2 -> 2790 | C30: =B30*1.05 -> 2929.5 | D30: =C30*1.1 -> 3222.45
A31: MB Standard, XL,XXL-Extended Warr.-3 yr | B31: =B29*3 -> 4185 | C31: =B31*1.05 -> 4394.25 | D31: =C31*1.1 -> 4833.675
A32: Motorized MediBoom Extended Warranty 1yr | B32: 1395 | C32: =B32*1.05 -> 1464.75 | D32: =C32*1.1 -> 1611.225
A33: Motorized MediBoom Extended Warranty 2yr | B33: =B32*2 -> 2790 | C33: =B33*1.05 -> 2929.5 | D33: =C33*1.1 -> 3222.45
A34: Motorized MediBoom Extended Warranty 3yr | B34: =B32*3 -> 4185 | C34: =B34*1.05 -> 4394.25 | D34: =C34*1.1 -> 4833.675
A35: CEMOR Large MC Extended Warranty 1yr | B35: 1395 | C35: =B35*1.05 -> 1464.75 | D35: =C35*1.1 -> 1611.225
A36: CEMOR Large MC Extended Warranty 2yr | B36: =B35*2 -> 2790 | C36: =B36*1.05 -> 2929.5 | D36: =C36*1.1 -> 3222.45
A37: CEMOR Large MC Extended Warranty 3yr | B37: =B35*3 -> 4185 | C37: =B37*1.05 -> 4394.25 | D37: =C37*1.1 -> 4833.675
A38: SpacePoint Extended Warranty - 1 Year | B38: 825 | C38: =B38*1.05 -> 866.25 | D38: =C38*1.1 -> 952.875
A39: SpacePoint Extended Warranty - 2 Year | B39: =B38*2 -> 1650 | C39: =B39*1.05 -> 1732.5 | D39: =C39*1.1 -> 1905.75
A40: SpacePoint Extended Warranty - 3 Year | B40: =B38*3 -> 2475 | C40: =B40*1.05 -> 2598.75 | D40: =C40*1.1 -> 2858.625
A41: Valia Single,Dual,Triple Arm Ext Warr 1y | B41: 825 | C41: =B41*1.05 -> 866.25 | D41: =C41*1.1 -> 952.875
A42: Valia Single,Dual,Triple Arm Ext Warr 2y | B42: =B41*2 -> 1650 | C42: =B42*1.05 -> 1732.5 | D42: =C42*1.1 -> 1905.75
A43: Valia Single,Dual,Triple Arm Ext Warr 3y | B43: =B41*3 -> 2475 | C43: =B43*1.05 -> 2598.75 | D43: =C43*1.1 -> 2858.625

Sheet Booms and Lights
A1: Room Name | B1: Phases | C1: Config #1 | D1: Config #2 | E1: Config #3 | F1: Config #4 | G1: Config #5 | H1: Config #6 | I1: Config #7 | J1: Config #8 | K1: Config #9 | L1: Config #10 | Q1: Room Name | R1: Totals
A2: Configuration Name | C2: =IF('Config #1'!B2="","",'Config #1'!B2) -> LED/FP (Patient Left): Camera Capable with Wall Control | D2: =IF('Config #2'!B2="","",'Config #2'!B2) -> LED/FP (Patient Right) | E2: =IF('Config #3'!B2="","",'Config #3'!B2) -> Equipment Boom (Patient Foot) | F2: =IF('Config #4'!B2="","",'Config #4'!B2) -> Anesthesia Boom (Patient Right Shoulder) | G2: =IF('Config #5'!B2="","",'Config #5'!B2) | H2: =IF('Config #6'!B2="","",'Config #6'!B2) | I2: =IF('Config #7'!B2="","",'Config #7'!B2) | J2: =IF('Config #8'!B2="","",'Config #8'!B2) | K2: =IF('Config #9'!B2="","",'Config #9'!B2) | L2: =IF('Config #10'!B2="","",'Config #10'!B2) | N2: Shipping Per Phase | O2: Installation Per Phase | P2: Shipping and Installation Total | Q2: Configuration Name | R2: COG Total
A3: OR1 | B3: 1 | C3: 1 | D3: 1 | E3: 1 | F3: 1 | N3: =SUM(C3:L3)*250 -> 1000 | O3: =SUM(C3:L3)*2500 -> 10000 | P3: =N3*B3+O3*B3 -> 11000 | Q3: OR1 | R3: =SUM(C24*C3)+(D24*D3)+(E24*E3)+(F24*F3)+(G24*G3)+(H24*H3)+(I24*I3)+(J24*J3)+(K24*K3)+(L24*L3) -> 63322.521
N4: =SUM(C4:L4)*250 -> 0 | O4: =SUM(C4:L4)*2500 -> 0 | P4: =N4*B4+O4*B4 -> 0 | R4: =SUM(C24*C4)+(D24*D4)+(E24*E4)+(F24*F4)+(G24*G4)+(H24*H4)+(I24*I4)+(J24*J4)+(K24*K4)+(L24*L4) -> 0
N5: =SUM(C5:L5)*250 -> 0 | O5: =SUM(C5:L5)*2500 -> 0 | P5: =N5*B5+O5*B5 -> 0 | R5: =SUM(C24*C5)+(D24*D5)+(E24*E5)+(F24*F5)+(G24*G5)+(H24*H5)+(I24*I5)+(J24*J5)+(K24*K5)+(L24*L5) -> 0
N6: =SUM(C6:L6)*250 -> 0 | O6: =SUM(C6:L6)*2500 -> 0 | P6: =N6*B6+O6*B6 -> 0 | R6: =SUM(C24*C6)+(D24*D6)+(E24*E6)+(F24*F6)+(G24*G6)+(H24*H6)+(I24*I6)+(J24*J6)+(K24*K6)+(L24*L6) -> 0
N7: =SUM(C7:L7)*250 -> 0 | O7: =SUM(C7:L7)*2500 -> 0 | P7: =N7*B7+O7*B7 -> 0 | R7: =SUM(C24*C7)+(D24*D7)+(E24*E7)+(F24*F7)+(G24*G7)+(H24*H7)+(I24*I7)+(J24*J7)+(K24*K7)+(L24*L7) -> 0
N8: =SUM(C8:L8)*250 -> 0 | O8: =SUM(C8:L8)*2500 -> 0 | P8: =N8*B8+O8*B8 -> 0 | R8: =SUM(C3*C8)+(D3*D8)+(E3*E8)+(F3*F8)+(G3*G8)+(H3*H8)+(I3*I8)+(J3*J8)+(K3*K8)+(L3*L8) -> 0
N9: =SUM(C9:L9)*250 -> 0 | O9: =SUM(C9:L9)*2500 -> 0 | P9: =N9*B9+O9*B9 -> 0 | R9: =SUM(C4*C9)+(D4*D9)+(E4*E9)+(F4*F9)+(G4*G9)+(H4*H9)+(I4*I9)+(J4*J9)+(K4*K9)+(L4*L9) -> 0
N10: =SUM(C10:L10)*250 -> 0 | O10: =SUM(C10:L10)*2500 -> 0 | P10: =N10*B10+O10*B10 -> 0 | R10: =SUM(C5*C10)+(D5*D10)+(E5*E10)+(F5*F10)+(G5*G10)+(H5*H10)+(I5*I10)+(J5*J10)+(K5*K10)+(L5*L10) -> 0
N11: =SUM(C11:L11)*250 -> 0 | O11: =SUM(C11:L11)*2500 -> 0 | P11: =N11*B11+O11*B11 -> 0 | R11: =SUM(C6*C11)+(D6*D11)+(E6*E11)+(F6*F11)+(G6*G11)+(H6*H11)+(I6*I11)+(J6*J11)+(K6*K11)+(L6*L11) -> 0
N12: =SUM(C12:L12)*250 -> 0 | O12: =SUM(C12:L12)*2500 -> 0 | P12: =N12*B12+O12*B12 -> 0 | R12: =SUM(C7*C12)+(D7*D12)+(E7*E12)+(F7*F12)+(G7*G12)+(H7*H12)+(I7*I12)+(J7*J12)+(K7*K12)+(L7*L12) -> 0
A13: TOTAL CONFIGURATIONS | C13: =IF(SUM(C3:C12)=0,"",(SUM(C3:C12))) -> 1 | D13: =IF(SUM(D3:D12)=0,"",(SUM(D3:D12))) -> 1 | E13: =IF(SUM(E3:E12)=0,"",(SUM(E3:E12))) -> 1 | F13: =IF(SUM(F3:F12)=0,"",(SUM(F3:F12))) -> 1 | G13: =IF(SUM(G3:G12)=0,"",(SUM(G3:G12))) | H13: =IF(SUM(H3:H12)=0,"",(SUM(H3:H12))) | I13: =IF(SUM(I3:I12)=0,"",(SUM(I3:I12))) | J13: =IF(SUM(J3:J12)=0,"",(SUM(J3:J12))) | ... L13: =IF(SUM(L3:L12)=0,"",(SUM(L3:L12))) | Q13: TOTAL CONFIGURATIONS | R13: =SUM(C13:L13) -> 4
A14: Simeon COG | C14: =SUM('Config #1'!E67) -> 19747.706 | D14: =SUM('Config #2'!E67) -> 16767.65 | E14: =SUM('Config #3'!E67) -> 0 | F14: =SUM('Config #4'!E67) -> 0 | G14: =SUM('Config #5'!E67) -> 0 | H14: =SUM('Config #6'!E67) -> 0 | I14: =SUM('Config #7'!E67) -> 0 | J14: =SUM('Config #8'!E67) -> 16856.855 | K14: =SUM('Config #9'!E67) -> 0 | L14: =SUM('Config #10'!E67) -> 0
A15: Ondal COG | C15: =('Config #1'!E27)+('Config #1'!E51) -> 0 | D15: =SUM('Config #2'!E27)+('Config #2'!E51) -> 0 | E15: =SUM('Config #3'!E27)+('Config #3'!E51) -> 15494.532 | F15: =SUM('Config #4'!E27)+('Config #4'!E51) -> 11312.632 | G15: =SUM('Config #5'!E27)+('Config #5'!E51) -> 0 | H15: =SUM('Config #6'!E27)+('Config #6'!E51) -> 0 | I15: =SUM('Config #7'!E27)+('Config #7'!E51) -> 0 | J15: =SUM('Config #8'!E27)+('Config #8'!E51) -> 0 | K15: =SUM('Config #9'!E27)+('Config #9'!E51) -> 0 | L15: =SUM('Config #10'!E27)+('Config #10'!E51) -> 0
A16: Ext. Simeon COG | C16: =SUM(C3:C7)*C14 -> 19747.706 | D16: =SUM(D3:D7)*D14 -> 16767.65 | E16: =SUM(E3:E7)*E14 -> 0 | F16: =SUM(F3:F7)*F14 -> 0 | G16: =SUM(G3:G7)*G14 -> 0 | H16: =SUM(H3:H7)*H14 -> 0 | I16: =SUM(I3:I7)*I14 -> 0 | J16: =SUM(J3:J7)*J14 -> 0 | ... L16: =SUM(L3:L7)*L14 -> 0 | Q16: Ext. Simeon COG | R16: =SUM(C16:L16) -> 36515.356
A17: Ext. Ondal COG | C17: =SUM(C3:C7)*C15 -> 0 | D17: =SUM(D3:D7)*D15 -> 0 | E17: =SUM(E3:E7)*E15 -> 15494.532 | F17: =SUM(F3:F7)*F15 -> 11312.632 | G17: =SUM(G3:G7)*G15 -> 0 | H17: =SUM(H3:H7)*H15 -> 0 | I17: =SUM(I3:I7)*I15 -> 0 | J17: =SUM(J3:J7)*J15 -> 0 | ... L17: =SUM(L3:L7)*L15 -> 0 | Q17: Ext. Ondal COG | R17: =SUM(C17:L17) -> 26807.165
A18: Ext. Simeon and Ondal COG | C18: =C24*SUM(C3:C12) -> 19747.706 | D18: =D24*SUM(D3:D12) -> 16767.65 | E18: =E24*SUM(E3:E12) -> 15494.532 | F18: =F24*SUM(F3:F12) -> 11312.632 | G18: =G24*SUM(G3:G12) -> 0 | H18: =H24*SUM(H3:H12) -> 0 | I18: =I24*SUM(I3:I12) -> 0 | J18: =J24*SUM(J3:J12) -> 0 | ... L18: =L24*SUM(L3:L12) -> 0 | Q18: Ext. Simeon & Ondal COG | R18: =SUM(C18:L18) -> 63322.521
Q19: Tarriffs (10%) | R19: =R18*0.1 -> 6332.2521
Q20: Equipment Total | R20: =SUM(R18:R19) -> 69654.773
Q21: Shipping & Install COG | R21: =SUM(P3:P12) -> 11000
Q22: Grand Total COG | R22: =SUM(R20:R21) -> 80654.773
A23: V-- BNL SUPPLIER UNIT COG --V | Q23: List Price @ 40% CM | R23: =R22/(1-0.4) -> 134424.62
A24: Simeon and Ondal COG | C24: =SUM(C14:C15) -> 19747.706 | D24: =SUM(D14:D15) -> 16767.65 | E24: =SUM(E14:E15) -> 15494.532 | F24: =SUM(F14:F15) -> 11312.632 | G24: =SUM(G14:G15) -> 0 | H24: =SUM(H14:H15) -> 0 | I24: =SUM(I14:I15) -> 0 | J24: =SUM(J14:J15) -> 16856.855 | ... L24: =SUM(L14:L15) -> 0 | N24: Shipping | O24: Installation | P24: Total
A25: Configuration List Price | C25: =IF(ISBLANK('Config #1'!B70),0,'Config #1'!B70) -> 65825.687 | D25: =IF(ISBLANK('Config #2'!B70),0,'Config #2'!B70) -> 55892.167 | E25: =IF(ISBLANK('Config #3'!B70),0,'Config #3'!B70) -> 51648.442 | F25: =IF(ISBLANK('Config #4'!B70),0,'Config #4'!B70) -> 37708.775 | G25: =IF(ISBLANK('Config #5'!B70),0,'Config #5'!B70) -> 0 | H25: =IF(ISBLANK('Config #6'!B70),0,'Config #6'!B70) -> 0 | I25: =IF(ISBLANK('Config #7'!B70),0,'Config #7'!B70) -> 0 | J25: =IF(ISBLANK('Config #8'!B70),0,'Config #8'!B70) -> 56189.517 | K25: =IF(ISBLANK('Config #9'!B70),0,'Config #9'!B70) -> 0 | L25: =IF(ISBLANK('Config #10'!B70),0,'Config #10'!B70) -> 0
A26: Ext. Config List Total | C26: =C25*SUM(C3:C12) -> 65825.687 | D26: =D25*SUM(D3:D12) -> 55892.167 | E26: =E25*SUM(E3:E12) -> 51648.442 | F26: =F25*SUM(F3:F12) -> 37708.775 | G26: =G25*SUM(G3:G12) -> 0 | H26: =H25*SUM(H3:H12) -> 0 | I26: =I25*SUM(I3:I12) -> 0 | J26: =J25*SUM(J3:J12) -> 0 | ... L26: =L25*SUM(L3:L12) -> 0
A29: Boom and Light Details
A30: 3D Configurations Link
A31: Competitor Quotes Link
A32: Power Type
A33: Gas Connection Type
A34: Ceiling Height
A35: Pricing Displayed
A36: Summary Page Details
A37: General Notes
A40: Additional Items | B40: Included? | C40: Quote Display
A41: Support+ | Promise
A42: Support+ | In-Case
A43: Support+ | Bio-Med
A44: Project Management
...

Sheet Estimating Drop Downs
A1: Divisons Included? | B1: Pricing Format | C1: Pricing Shown | D1: Quantity | E1: Feet | F1: Inches | G1: On-Grade? | H1: Floors Above? | I1: Room Type | J1: Construction Type | K1: Deposit | L1: Nurse Call | M1: HVAC Controls | N1: Power Type | O1: Gas Connection Type
A3: Yes | B3: Standard | C3: Lump Sum | D3: 1 | E3: 1 ft | F3: 0.5 in | G3: No | H3: No | I3: Cath / IR | J3: Finishes Refresh | K3: No, 0% | L3: Hill-Rom | M3: Johnson Controls | N3: Isolated (Orange Brown) | O3: Ohmeda
A4: No | B4: Baylor | C4: Groups Only | D4: 2 | E4: 2 ft | F4: 1 in | G4: Yes | H4: Yes | I4: Clinic Support Space | J4: Equipment Replacement | K4: Yes, 5% | L4: Rauland | M4: Siemens | N4: Non-Isolated (Black/White) | O4: Chemetron
A5: TBD | B5: HCA | C5: Line item Pricing | D5: 3 | E5: 3 ft | F5: 1.5 in | I5: CT | J5: Space Conversion | K5: Yes, 10% | M5: Trane | O5: Puritan Bennett
D6: 4 | E6: 4 ft | F6: 2 in | I6: Imaging Renovation | J6: New Build / Addition | K6: Yes, 15% | M6: Other | O6: DISS
D7: 5 | E7: 5 ft | F7: 2.5 in | I7: Linear Accelerator | K7: Yes, 20% | O7: Other
D8: 6 | E8: 6 ft | F8: 3 in | I8: Lobby/Non-Critical | K8: Yes, 25%
D9: 7 | E9: 7 ft | F9: 3.5 in | I9: Medical Office Building | K9: Yes, 30%
D10: 8 | E10: 8 ft | F10: 4 in | I10: MRI | K10: Yes, 35%
D11: 9 | E11: 9 ft | F11: 4.5 in | I11: New Build | K11: Other
D12: 10 | E12: 10 ft | F12: 5 in | I12: OR Renovation
D13: 11 | E13: 11 ft | F13: 5.5 in | I13: Other
D14: 12 | E14: 12 ft | F14: 6 in | I14: Patient Rooms
D15: 13 | E15: 13 ft | F15: 6.5 in | I15: Pharmacy / Lab
D16: 14 | E16: 14 ft | F16: 7 in | I16: Shell Buildout
D17: 15 | E17: 15 ft | F17: 7.5 in | I17: SPD
D18: 16 | E18: 16 ft | F18: 8 in | I18: Tenant Improvement
D19: 17 | E19: 17 ft | F19: 8.5 in | I19: X-Ray
D20: 18 | E20: 18 ft | F20: 9 in
D21: 19 | E21: 19 ft | F21: 9.5 in
D22: 20 | E22: 20 ft | F22: 10 in
F23: 10.5 in
F24: 11 in
F25: 11.5 in

Sheet BnL Drop Downs
A1: Service Types | B1: Service Head Height | C1: Rear Selection | D1: Connection Type | E1: Power Type | F1: Ceiling Tube | G1: Ceiling Cover
B2: Articulating | C2: ="--Not Selected--" -> --Not Selected--
A3: (2) Duplexes | B3: 600mm | C3: Data Pass Thru | D3: Ohmeda | E3: Isolated | F3: 100mm | G3: Single
A4: (3) Duplexes | B4: 800mm | C4: Nitrogen Regulator | D4: Chemetron | E4: Non-Isolated | F4: 300mm | G4: Tandem (1st Position)
A5: Oxygen | B5: 1000mm | D5: Puritan Bennett | F5: 500mm | G5: Tandem (2nd Position)
A6: Medical Air | B6: 1200mm | D6: DISS
A7: Nitrous Oxide | B7: 1400mm
A8: Vacuum | B8: 1600mm
A9: Nitrogen
A10: Carbon Dioxide
A11: WAGD
A12: Data
A13: Storz 4in1
A14: Blank

Sheet Ondal Booms
A2: Base Model | B2: Base Model Sales Price | C2: Ondal List | D2: Ondal Sales | E2: Imagine List | H2: Ondal Discount | I2: Imagine Margin
B3: =""
A4: 1 | B4: Spring | C4: =C14-$C$206 -> 10983.36 | D4: =C4*(1-$H$4) -> 8237.52 | E4: =D4/(1-$I$4)*2 -> 27458.4 | H4: 0.25 | I4: 0.4
A5: 2 | B5: Spring XL | C5: =C15-$C$206 -> 12891.69 | D5: =C5*(1-$H$4) -> 9668.7675 | E5: =D5/(1-$I$4)*2 -> 32229.225
A6: 3 | B6: Powered | C6: =C16-$C$206 -> 11815.05 | D6: =C6*(1-$H$4) -> 8861.2875 | E6: =D6/(1-$I$4)*2 -> 29537.625
A7: 4 | B7: Powered XL | C7: =C17-$C$206 -> 13425.94 | D7: =C7*(1-$H$4) -> 10069.455 | E7: =D7/(1-$I$4)*2 -> 33564.85
A8: 5 | B8: Fixed | C8: =C18-$C$206 -> 7473.19 | D8: =C8*(1-$H$4) -> 5604.8925 | E8: =D8/(1-$I$4)*2 -> 18682.975
A9: 6 | B9: Fixed XL | C9: =C19-$C$206 -> 8900.5 | D9: =C9*(1-$H$4) -> 6675.375 | E9: =D9/(1-$I$4)*2 -> 22251.25
A10: 7 | B10: Fixed XXL | C10: =C20-$C$206 -> 10274.96 | D10: =C10*(1-$H$4) -> 7706.22 | E10: =D10/(1-$I$4)*2 -> 25687.4
B12: Base Model | C12: Ondal List | D12: Ondal Sales | E12: Imagine List | F12: Price Adder | H12: Ceiling Cover | I12: Ceiling Flange | J12: Top Arm | K12: Bottom Arm | L12: Service Head | M12: Misc
B13: =""
A14: 1 | B14: Spring | C14: 11372.18 | D14: =C14*(1-$H$4) -> 8529.135 | E14: =D14/(1-$I$4)*2 -> 28430.45 | F14: 0 | H14: Single | I14: 100mm | J14: =B68 -> 1200mm | K14: Spring | L14: 400mm
A15: 2 | B15: Spring XL | C15: 13280.51 | D15: =C15*(1-$H$4) -> 9960.3825 | E15: =D15/(1-$I$4)*2 -> 33201.275 | F15: 0 | H15: Single | I15: 100mm XL | J15: =B72 -> 1200mm XL | K15: Spring | L15: 400mm
A16: 3 | B16: Powered | C16: 12203.87 | D16: =C16*(1-$H$4) -> 9152.9025 | E16: =D16/(1-$I$4)*2 -> 30509.675 | F16: 0 | H16: Single | I16: 100mm | J16: =B68 -> 1200mm | K16: Powered | L16: 400mm
A17: 4 | B17: Powered XL | C17: 13814.76 | D17: =C17*(1-$H$4) -> 10361.07 | E17: =D17/(1-$I$4)*2 -> 34536.9 | F17: 0 | H17: Single | I17: 100mm XL | J17: =B72 -> 1200mm XL | K17: Powered | L17: 400mm
A18: 5 | B18: Fixed | C18: 7862.01 | D18: =C18*(1-$H$4) -> 5896.5075 | E18: =D18/(1-$I$4)*2 -> 19655.025 | F18: 0 | H18: Single | I18: 100mm | J18: =B68 -> 1200mm | K18: Fixed | L18: 400mm
A19: 6 | B19: Fixed XL | C19: 9289.32 | D19: =C19*(1-$H$4) -> 6966.99 | E19: =D19/(1-$I$4)*2 -> 23223.3 | F19: 0 | H19: Single | I19: 100mm XL | J19: =B72 -> 1200mm XL | K19: Fixed | L19: 400mm
A20: 7 | B20: Fixed XXL | C20: 10663.78 | D20: =C20*(1-$H$4) -> 7997.835 | E20: =D20/(1-$I$4)*2 -> 26659.45 | F20: 0 | H20: Single | I20: 100mm XL | J20: =B72 -> 1200mm XL | K20: Fixed | L20: 400mm
B22: Spring - Large Monitor Boom | C22: =16600.73 -> 16600.73 | D22: =C22*(1-$H$4) -> 12450.548 | E22: =D22/(1-$I$4)*2 -> 41501.825 | F22: =C22-C14 -> 5228.55 | H22: Single | I22: 100mm | J22: =B68 -> 1200mm | K22: Spring | L22: =B106 -> Large Monitor Carrier
B23: Spring XL - Large Monitor Boom | C23: =18509.06 -> 18509.06 | D23: =C23*(1-$H$4) -> 13881.795 | E23: =D23/(1-$I$4)*2 -> 46272.65 | F23: =C23-C15 -> 5228.55 | H23: Single | I23: 100mm XL | J23: =B72 -> 1200mm XL | K23: Spring | L23: Large Monitor Carrier
B24: Powered - 200SH | C24: 11707.68 | D24: =C24*(1-$H$4) -> 8780.76 | E24: =D24/(1-$I$4)*2 -> 29269.2 | F24: =(C24-$C$16) -> -496.19 | H24: Single | I24: 100mm | J24: =$B$68 -> 1200mm | K24: Spring | L24: 200mm
B25: Powered - 600SH | C25: 12701.91 | D25: =C25*(1-$H$4) -> 9526.4325 | E25: =D25/(1-$I$4)*2 -> 31754.775 | F25: =(C25-$C$16) -> 498.04 | H25: Single | I25: 100mm | J25: =$B$68 -> 1200mm | K25: Spring | L25: 600mm
B26: Powered - 800SH | C26: 13222.18 | D26: =C26*(1-$H$4) -> 9916.635 | E26: =D26/(1-$I$4)*2 -> 33055.45 | F26: =(C26-$C$16) -> 1018.31 | H26: Single | I26: 100mm | J26: =$B$68 -> 1200mm | K26: Spring | L26: 800mm
B27: Powered - 1000SH | C27: 13740.59 | D27: =C27*(1-$H$4) -> 10305.443 | E27: =D27/(1-$I$4)*2 -> 34351.475 | F27: =(C27-$C$16) -> 1536.72 | H27: Single | I27: 100mm | J27: =$B$68 -> 1200mm | K27: Spring | L27: 1000mm
B28: Powered - N2 Regulator | C28: 12993.59 | D28: =C28*(1-$H$4) -> 9745.1925 | E28: =D28/(1-$I$4)*2 -> 32483.975 | F28: =(C28-$C$16) -> 789.72 | H28: Single | I28: 100mm | J28: =$B$68 -> 1200mm | K28: Spring | L28: 1000mm
B29: Powered - (3) 500 Shelves | C29: 13746.19 | D29: =C29*(1-$H$4) -> 10309.642 | E29: =D29/(1-$I$4)*2 -> 34365.475 | F29: =(C29-$C$16) -> 1542.32 | H29: Single | I29: 100mm | J29: =$B$68 -> 1200mm | K29: Spring | L29: 100mm
B30: Powered - (3) 750 Shelves | C30: 14534.92 | D30: =C30*(1-$H$4) -> 10901.19 | E30: =D30/(1-$I$4)*2 -> 36337.3 | F30: =(C30-$C$16) -> 2331.05 | H30: Single | I30: 100mm | J30: =$B$68 -> 1200mm | K30: Spring | L30: 100mm
B31: Powered - 300mm Ceiling Flange | C31: 12258.3 | D31: =C31*(1-$H$4) -> 9193.725 | E31: =D31/(1-$I$4)*2 -> 30645.75 | F31: =(C31-$C$16) -> 54.43 | H31: Single | I31: 100mm | J31: =$B$68 -> 1200mm | K31: Spring | L31: 100mm
B32: Powered - 500mm Ceiling Flange | C32: 12389.02 | D32: =C32*(1-$H$4) -> 9291.765 | E32: =D32/(1-$I$4)*2 -> 30972.55 | F32: =(C32-$C$16) -> 185.15 | H32: Single | I32: 100mm | J32: =$B$68 -> 1200mm | K32: Spring | L32: 100mm
B33: Powered - One O2 Outlet | C33: 12590.84 | D33: =C33*(1-$H$4) -> 9443.13 | E33: =D33/(1-$I$4)*2 -> 31477.1 | F33: =(C33-$C$16) -> 386.97 | H33: Single | I33: 100mm | J33: 1200mm XL | K33: Spring | L33: 100mm
B34: Powered - Two O2 Outlet | C34: 12855.61 | D34: =C34*(1-$H$4) -> 9641.7075 | E34: =D34/(1-$I$4)*2 -> 32139.025 | F34: =(C34-$C$16) -> 651.74 | H34: Single | I34: 100mm | J34: 1200mm XL | K34: Spring | L34: 100mm
B35: Powered - Three O2 Outlet | C35: 13120.38 | D35: =C35*(1-$H$4) -> 9840.285 | E35: =D35/(1-$I$4)*2 -> 32800.95 | F35: =(C35-$C$16) -> 916.51 | H35: Single | I35: 100mm | J35: 1200mm XL | K35: Spring | L35: 100mm
B36: Powered - Four O2 Outlet | C36: 13385.15 | D36: =C36*(1-$H$4) -> 10038.862 | E36: =D36/(1-$I$4)*2 -> 33462.875 | F36: =(C36-$C$16) -> 1181.28 | H36: Single | I36: 100mm | J36: 1200mm XL | K36: Spring | L36: 100mm
B37: Powered - Four Duplex | C37: 12529.74 | D37: =C37*(1-$H$4) -> 9397.305 | E37: =D37/(1-$I$4)*2 -> 31324.35 | F37: =(C37-$C$16) -> 325.87 | H37: Single | I37: 100mm | J37: 1200mm XL | K37: Spring | L37: 100mm
B38: Powered - Six Duplex | C38: 12700.07 | D38: =C38*(1-$H$4) -> 9525.0525 | E38: =D38/(1-$I$4)*2 -> 31750.175 | F38: =(C38-$C$16) -> 496.2 | H38: Single | I38: 100mm | J38: 1200mm XL | K38: Spring | L38: 100mm
B39: Powered - Eight Duplex | C39: 12855.61 | D39: =C39*(1-$H$4) -> 9641.7075 | E39: =D39/(1-0.4)*2 -> 32139.025 | F39: =(C39-$C$16) -> 651.74 | H39: Single | I39: 100mm | J39: 1200mm XL | K39: Spring | L39: 100mm
B40: Powered - Twelve Duplex | C40: 13125.91 | D40: =C40*(1-$H$4) -> 9844.4325 | E40: =D40/(1-0.4)*2 -> 32814.775 | F40: =(C40-$C$16) -> 922.04 | H40: Single | I40: 100mm | J40: 1200mm XL | K40: Spring | L40: 100mm
B41: Powered XL - 300mm XL Ceiling Flange | C41: 13471.21 | D41: =C41*(1-$H$4) -> 10103.407 | E41: =D41/(1-$I$4)*2 -> 33678.025 | F41: =(C41-$C$15) -> 190.7 | H41: Single | I41: 100mm | J41: 1200mm XL | K41: Spring | L41: 100mm
B42: Powered XL - 500mm XL Ceiling Flange | C42: 13735.58 | D42: =C42*(1-$H$4) -> 10301.685 | E42: =D42/(1-$I$4)*2 -> 34338.95 | F42: =(C42-$C$15) -> 455.07 | H42: Single | I42: 100mm | J42: 1200mm XL | K42: Spring | L42: 100mm
B43: Spring XL - 1400mm XL Top Arm | C43: 13937.61 | D43: =C43*(1-$H$4) -> 10453.208 | E43: =D43/(1-$I$4)*2 -> 34844.025 | F43: =(C43-$C$15) -> 657.1 | H43: Single | I43: 100mm | J43: 1200mm XL | K43: Spring | L43: 100mm
...

Sheet Simeon Lights
A1: Base Model(s) | D1: 0 | N1: DISCOUNTS | R1: MARGIN
B2: Part # | C2: Base Model | D2: # of Lights | E2: TC Mount? | F2: Simeon List | G2: Simeon Sales | H2: Imagine List | I2: Ceiling Tube | J2: Central Axis | K2: Turning Cover | M2: Surgical Light | N2: Camera Systems | O2: Exam Lights | P2: Client Discount | R2: Imagine Margin
B4: 11-100-101 | C4: LED | D4: 1 | E4: No | F4: =G4/(1-$M$4) -> 4142.87 | G4: =SUM(I4:K4) -> 2071.435 | H4: =G4/(1-$R$4)*2 -> 6904.7833 | I4: =G225 -> 351.69 | J4: =G124 -> 1719.745 | K4: 0 | M4: 0.5 | N4: 0.45 | O4: 0.45 | P4: 0.5 | R4: 0.4
B5: 11-100-102 | C5: LED / LED | D5: 2 | E5: No | F5: =G5/(1-$M$4) -> 7827.25 | G5: =SUM(I5:K5) -> 3913.625 | H5: =G5/(1-$R$4)*2 -> 13045.417 | I5: =G225 -> 351.69 | J5: =G134 -> 3561.935 | K5: 0
B6: 11-100-103 | C6: LED / LED / LED | D6: 3 | E6: No | F6: =G6/(1-$M$4) -> 10639.91 | G6: =SUM(I6:K6) -> 5319.955 | H6: =G6/(1-$R$4)*2 -> 17733.183 | I6: =G225 -> 351.69 | J6: =G143 -> 4968.265 | K6: 0
B7: 11-100-104 | C7: LED / FP | D7: 1 | E7: No | F7: =G7/(1-$M$4) -> 5874.23 | G7: =SUM(I7:K7) -> 2937.115 | H7: =G7/(1-$R$4)*2 -> 9790.3833 | I7: =G225 -> 351.69 | J7: =G132 -> 2585.425 | K7: =0 -> 0
B8: 11-100-105 | C8: FP / LED | D8: 1 | E8: No | F8: =G8/(1-$M$4) -> 6214.45 | G8: =SUM(I8:K8) -> 3107.225 | H8: =G8/(1-$R$4)*2 -> 10357.417 | I8: =G225 -> 351.69 | J8: =G133 -> 2574.84 | K8: =G181 -> 180.695
B9: 11-100-106 | C9: LED / LED / FP | D9: 2 | E9: No | F9: =G9/(1-$M$4) -> 8860.93 | G9: =SUM(I9:K9) -> 4430.465 | H9: =G9/(1-$R$4)*2 -> 14768.217 | I9: =G225 -> 351.69 | J9: =G141 -> 4078.775 | K9: =0 -> 0
B10: 11-100-107 | C10: FP / LED / FP | D10: 1 | E10: No | F10: =G10/(1-$M$4) -> 8244.23 | G10: =SUM(I10:K10) -> 4122.115 | H10: =G10/(1-$R$4)*2 -> 13740.383 | I10: =G225 -> 351.69 | J10: =G142 -> 3589.73 | K10: =G181 -> 180.695
B11: 11-100-108 | C11: LED / LS | D11: 1 | E11: No | F11: =G11/(1-$M$4) -> 7827.25 | G11: =SUM(I11:K11) -> 3913.625 | H11: =G11/(1-$R$4)*2 -> 13045.417 | I11: =G225 -> 351.69 | J11: =G134 -> 3561.935 | K11: 0
B12: 11-100-109 | C12: LED / LED / LS | D12: 2 | E12: No | F12: =G12/(1-$M$4) -> 10639.91 | G12: =SUM(I12:K12) -> 5319.955 | H12: =G12/(1-$R$4)*2 -> 17733.183 | I12: =G225 -> 351.69 | J12: =G143 -> 4968.265 | K12: 0
B13: 11-100-110 | C13: FP | D13: 0 | E13: No | F13: =G13/(1-$M$4) -> 3442.5 | G13: =SUM(I13:K13) -> 1721.25 | H13: =G13/(1-$R$4)*2 -> 5737.5 | I13: =G225 -> 351.69 | J13: =G125 -> 1369.56 | K13: 0
B14: 11-100-111 | C14: LS | D14: 0 | E14: No | F14: =G14/(1-$M$4) -> 4142.87 | G14: =SUM(I14:K14) -> 2071.435 | H14: =G14/(1-$R$4)*2 -> 6904.7833 | I14: =G225 -> 351.69 | J14: =G124 -> 1719.745 | K14: 0
B15: 11-100-112 | C15: FP / FP | D15: 0 | E15: No | F15: =G15/(1-$M$4) -> 5388.37 | G15: =SUM(I15:K15) -> 2694.185 | H15: =G15/(1-$R$4)*2 -> 8980.6167 | I15: =G225 -> 351.69 | J15: =G135 -> 2161.8 | K15: =G181 -> 180.695
B16: 11-100-113 | C16: LS / LS | D16: 0 | E16: No | F16: =G16/(1-$M$4) -> 7827.25 | G16: =SUM(I16:K16) -> 3913.625 | H16: =G16/(1-$R$4)*2 -> 13045.417 | I16: =G225 -> 351.69 | J16: =G134 -> 3561.935 | K16: 0
B17: 11-100-114 | C17: FP / LS | D17: 0 | E17: No | F17: =G17/(1-$M$4) -> 5853.06 | G17: =SUM(I17:K17) -> 2926.53 | H17: =G17/(1-$R$4)*2 -> 9755.1 | I17: =G225 -> 351.69 | J17: =G133 -> 2574.84 | K17: 0
B18: 11-100-115 | C18: LS / FP | D18: 0 | E18: No | F18: =G18/(1-$M$4) -> 6235.62 | G18: =SUM(I18:K18) -> 3117.81 | H18: =G18/(1-$R$4)*2 -> 10392.7 | I18: =G225 -> 351.69 | J18: =G132 -> 2585.425 | K18: =G181 -> 180.695
B19: 11-100-116 | C19: (3P) LED | D19: 1 | E19: No | F19: =G19/(1-$M$4) -> 2878.16 | G19: =SUM(I19:K19) -> 1439.08 | H19: =G19/(1-$R$4)*2 -> 4796.9333 | I19: =G225 -> 351.69 | J19: =G126 -> 1087.39 | K19: 0
B20: 11-100-117 | C20: (3P) LED / LED | F20: =G20/(1-$M$4) -> 4532.29 | G20: =SUM(I20:K20) -> 2266.145 | H20: =G20/(1-$R$4)*2 -> 7553.8167 | I20: =G226 -> 351.69 | J20: =G136 -> 1914.455
B21: 11-100-118 | C21: UPGRADE | D21: 1 | E21: No | F21: =G21/(1-$M$4) -> 0 | G21: =SUM(I21:K21) -> 0 | H21: =G21/(1-$R$4)*2 -> 0 | I21: 0 | J21: 0 | K21: 0 | M21: 0.5 | N21: 0.4 | O21: 0.45 | P21: 0.5 | R21: 0.4
B22: 11-100-119 | C22: UPGRADE / UPGRADE | D22: 2 | E22: No | F22: =G22/(1-$M$4) -> 0 | G22: =SUM(I22:K22) -> 0 | H22: =G22/(1-$R$4)*2 -> 0 | I22: 0 | J22: 0 | K22: 0
B23: 11-100-120 | C23: UPGRADE / UPGRADE / UPGRADE | D23: 3 | E23: No | F23: =G23/(1-$M$4) -> 0 | G23: =SUM(I23:K23) -> 0 | H23: =G23/(1-$R$4)*2 -> 0 | I23: 0 | J23: 0 | K23: 0
A25: Priced Option(s)
B26: Part # | C26: Arm Selections | D26: Type | F26: Simeon List | G26: Imagine Cost | H26: Imagine List Price | I26: Spring Arm | J26: Lighthead | K26: Flat Panel | L26: Lead Shield | M26: Power Supply | N26: Power Cable | O26: Control Cable | P26: Patch Cable | Q26: Flat Panel Power Cable
B28: 11-200-101 | C28: ="7000 Standard" -> 7000 Standard | D28: LED | F28: =G28/(1-$M$4) -> 16918.19 | G28: =SUM(I28:Q28) -> 8459.095 | H28: =G28/(1-$R$4)*2 -> 28196.983 | I28: =G148 -> 1071.595 | J28: =G160 -> 6461.05 | K28: 0 | L28: 0 | M28: =$G$188 -> 744.63 | N28: =$G$189 -> 87.91 | O28: =$G$190 -> 60.27 | P28: =$G$191 -> 33.64 | Q28: 0
B29: 11-200-102 | C29: 7000 Low Ceiling | D29: LED | F29: =G29/(1-$M$4) -> 18316.85 | G29: =SUM(I29:Q29) -> 9158.425 | H29: =G29/(1-$R$4)*2 -> 30528.083 | I29: =G149 -> 1859.51 | J29: =G161 -> 6372.465 | K29: 0 | L29: 0 | M29: =$G$188 -> 744.63 | N29: =$G$189 -> 87.91 | O29: =$G$190 -> 60.27 | P29: =$G$191 -> 33.64 | Q29: 0
B30: 11-200-103 | C30: ="8000 Standard" -> 8000 Standard | D30: LED | F30: =G30/(1-$M$4) -> 18041.85 | G30: =SUM(I30:Q30) -> 9020.925 | H30: =G30/(1-$R$4)*2 -> 30069.75 | I30: =G148 -> 1071.595 | J30: =G155 -> 7022.88 | K30: 0 | L30: 0 | M30: =$G$188 -> 744.63 | N30: =$G$189 -> 87.91 | O30: =$G$190 -> 60.27 | P30: =$G$191 -> 33.64 | Q30: 0
B31: 11-200-104 | C31: 8000 Low Ceiling | D31: LED | F31: =G31/(1-$M$4) -> 19425.11 | G31: =SUM(I31:Q31) -> 9712.555 | H31: =G31/(1-$R$4)*2 -> 32375.183 | I31: =G149 -> 1859.51 | J31: =G156 -> 6926.595 | K31: 0 | L31: 0 | M31: =$G$188 -> 744.63 | N31: =$G$189 -> 87.91 | O31: =$G$190 -> 60.27 | P31: =$G$191 -> 33.64 | Q31: 0
B32: 11-200-105 | C32: 32in Flat Panel | D32: FP | F32: =G32/(1-$M$4) -> 8150.37 | G32: =SUM(I32:Q32) -> 4075.185 | H32: =G32/(1-$R$4)*2 -> 13583.95 | I32: =G150 -> 1850.235 | J32: =G210 -> 2195.955 | K32: 0 | L32: 0 | M32: 0 | N32: 0 | O32: 0 | P32: 0 | Q32: =G211 -> 28.995
B33: 11-200-106 | C33: Lead Shield | D33: LS | F33: =G33 -> 6449.6 | G33: =SUM(I33:Q33) -> 6449.6 | H33: =G33/(1-$R$4)*2 -> 21498.667 | I33: 0 | J33: 0 | K33: 0 | L33: =G214 -> 6449.6 | M33: 0 | N33: 0 | O33: 0 | P33: 0 | Q33: 0
C35: V-- NON-STANDARD --V | F35: =G35/(1-$M$4) -> 0 | G35: =SUM(I35:Q35) -> 0 | H35: =G35/(1-$R$4)*2 -> 0
B36: 11-200-107 | C36: 500 Standard | D36: LED | F36: =G36/(1-$M$4) -> 10337.15 | G36: =SUM(I36:Q36) -> 5168.575 | H36: =G36/(1-$R$4)*2 -> 17228.583 | I36: =G148 -> 1071.595 | J36: =G168 -> 4096.98
B37: 11-200-108 | C37: 500 Low Ceiling | D37: LED | F37: =G37/(1-$M$4) -> 11735.81 | G37: =SUM(I37:Q37) -> 5867.905 | H37: =G37/(1-$R$4)*2 -> 19559.683 | I37: =G149 -> 1859.51 | J37: =G169 -> 4008.395
B38: 11-200-109 | C38: 500 Standard (3P) | D38: LED | F38: =G38/(1-$M$4) -> 10726.83 | G38: =SUM(I38:Q38) -> 5363.415 | H38: =G38/(1-$R$4)*2 -> 17878.05 | I38: =G146 -> 561.445 | J38: =G166 -> 3875.52 | K38: 0 | L38: 0 | M38: =$G$188 -> 744.63 | N38: =$G$189 -> 87.91 | O38: =$G$190 -> 60.27 | P38: =$G$191 -> 33.64 | Q38: 0
B39: 11-200-110 | C39: 500 Low Ceiling (3P) | D39: LED | F39: =G39/(1-$M$4) -> 11633.12 | G39: =SUM(I39:Q39) -> 5816.56 | H39: =G39/(1-$R$4)*2 -> 19388.533 | I39: =G147 -> 1103.18 | J39: =G167 -> 3786.93 | K39: 0 | L39: 0 | M39: =$G$188 -> 744.63 | N39: =$G$189 -> 87.91 | O39: =$G$190 -> 60.27 | P39: =$G$191 -> 33.64 | Q39: 0
B40: 11-200-111 | C40: 7000 Standard (3P) | D40: LED | F40: =G40/(1-$M$4) -> 15468.27 | G40: =SUM(I40:Q40) -> 7734.135 | H40: =G40/(1-$R$4)*2 -> 25780.45 | I40: =G146 -> 561.445 | J40: =G162 -> 6246.24 | K40: 0 | L40: 0 | M40: =$G$188 -> 744.63 | N40: =$G$189 -> 87.91 | O40: =$G$190 -> 60.27 | P40: =$G$191 -> 33.64 | Q40: 0
B41: 11-200-112 | C41: 7000 Low Ceiling (3P) | D41: LED | F41: =G41/(1-$M$4) -> 16372.35 | G41: =SUM(I41:Q41) -> 8186.175 | H41: =G41/(1-$R$4)*2 -> 27287.25 | I41: =G147 -> 1103.18 | J41: =G163 -> 6156.545 | K41: 0 | L41: 0 | M41: =$G$188 -> 744.63 | N41: =$G$189 -> 87.91 | O41: =$G$190 -> 60.27 | P41: =$G$191 -> 33.64 | Q41: 0
B42: 11-200-113 | C42: 8000 Standard (3P) | D42: LED | F42: =G42/(1-$M$4) -> 16554.57 | G42: =SUM(I42:Q42) -> 8277.285 | H42: =G42/(1-$R$4)*2 -> 27590.95 | I42: =G146 -> 561.445 | J42: =G153 -> 6789.39 | K42: 0 | L42: 0 | M42: =$G$188 -> 744.63 | N42: =$G$189 -> 87.91 | O42: =$G$190 -> 60.27 | P42: =$G$191 -> 33.64 | Q42: 0
B43: 11-200-114 | C43: 8000 Low Ceiling (3P) | D43: LED | F43: =G43/(1-$M$4) -> 17443.06 | G43: =SUM(I43:Q43) -> 8721.53 | H43: =G43/(1-$R$4)*2 -> 29071.767 | I43: =G147 -> 1103.18 | J43: =G154 -> 6691.9 | K43: 0 | L43: 0 | M43: =$G$188 -> 744.63 | N43: =$G$189 -> 87.91 | O43: =$G$190 -> 60.27 | P43: =$G$191 -> 33.64 | Q43: 0
B44: 11-200-115 | C44: ="UPGRADE - SPECIAL PRICING" -> UPGRADE - SPECIAL PRICING | D44: LED | F44: =G44/(1-$M$4) -> 15000 | G44: =SUM(I44:Q44) -> 7500 | H44: =G44/(1-$R$4)*2 -> 25000 | I44: 0 | J44: =G159 -> 7500 | K44: 0 | L44: 0 | M44: 0 | N44: 0 | O44: 0 | P44: 0 | Q44: 0
...

Sheet Cost Analysis
C2: CONFIGURATION DESCRIPTION | D2: ONDAL QUOTE | E2: IMAGINE EXCEL | F2: DELTA | H2: SIMEON QUOTE | I2: TANDEM | J2: HANDLE ADT. | K2: WCP BACKBOX | L2: IMAGINE EXCEL | M2: DELTA
B3: Config #1 | C3: =IF(ISBLANK('Config #1'!B2),"",'Config #1'!B2) -> LED/FP (Patient Left): Camera Capable with Wall Control | D3: 0 | E3: ='Config #1'!E27 -> 0 | F3: =E3-O3 -> 0 | I3: =IF('Config #1'!B55="Tandem (1st Position)",1317.19,0) -> 0 | J3: ='Config #1'!E63 -> 132 | K3: =IF(RIGHT('Config #1'!B60,1)=")",195,0) -> 195 | L3: ='Config #1'!E67 -> 19747.706 | M3: =L3-SUM(H3:K3) -> 19420.706
B4: Config #2 | C4: =IF(ISBLANK('Config #2'!B2),"",'Config #2'!B2) -> LED/FP (Patient Right) | D4: 0 | E4: ='Config #2'!E27 -> 0 | F4: =E4-O4 -> 0 | H4: 0 | I4: =IF('Config #2'!B55="Tandem (1st Position)",1317.19,0) -> 0 | J4: ='Config #2'!E63 -> 132 | K4: =IF(RIGHT('Config #2'!B60,1)=")",195,0) -> 0 | L4: ='Config #2'!E67 -> 16767.65 | M4: =L4-SUM(H4:K4) -> 16635.65
B5: Config #3 | C5: =IF(ISBLANK('Config #3'!B2),"",'Config #3'!B2) -> Equipment Boom (Patient Foot) | D5: 0 | E5: ='Config #3'!E27 -> 15494.532 | F5: =E5-O5 -> 15494.532 | H5: 0 | I5: =IF('Config #3'!B55="Tandem (1st Position)",1317.19,0) -> 0 | J5: ='Config #3'!E63 -> 0 | K5: =IF(RIGHT('Config #3'!B60,1)=")",195,0) -> 0 | L5: ='Config #3'!E67 -> 0 | M5: =L5-SUM(H5:K5) -> 0
B6: Config #4 | C6: =IF(ISBLANK('Config #4'!B2),"",'Config #4'!B2) -> Anesthesia Boom (Patient Right Shoulder) | D6: 0 | E6: ='Config #4'!E27 -> 11312.632 | F6: =E6-O6 -> 11312.632 | H6: 0 | I6: =IF('Config #4'!B55="Tandem (1st Position)",1317.19,0) -> 0 | J6: ='Config #4'!E63 -> 0 | K6: =IF(RIGHT('Config #4'!B60,1)=")",195,0) -> 0 | L6: ='Config #4'!E67 -> 0 | M6: =L6-SUM(H6:K6) -> 0
B7: Config #5 | C7: =IF(ISBLANK('Config #5'!B2),"",'Config #5'!B2) | D7: 0 | E7: ='Config #5'!E27 -> 0 | F7: =E7-O7 -> 0 | H7: 0 | I7: =IF('Config #5'!B55="Tandem (1st Position)",1317.19,0) -> 0 | J7: ='Config #5'!E63 -> 0 | K7: =IF(RIGHT('Config #5'!B60,1)=")",195,0) -> 0 | L7: ='Config #5'!E67 -> 0 | M7: =L7-SUM(H7:K7) -> 0
B8: Config #6 | C8: =IF(ISBLANK('Config #6'!B2),"",'Config #6'!B2) | D8: 0 | E8: ='Config #6'!E27 -> 0 | F8: =E8-O8 -> 0 | H8: 0 | I8: =IF('Config #6'!B55="Tandem (1st Position)",1317.19,0) -> 0 | J8: ='Config #6'!E63 -> 0 | K8: =IF(RIGHT('Config #6'!B60,1)=")",195,0) -> 0 | L8: ='Config #6'!E67 -> 0
B9: Config #7 | C9: =IF(ISBLANK('Config #7'!B2),"",'Config #7'!B2) | D9: 0 | E9: ='Config #7'!E27 -> 0 | F9: =E9-O9 -> 0 | H9: 0 | I9: =IF('Config #7'!B55="Tandem (1st Position)",1317.19,0) -> 0 | J9: ='Config #7'!E63 -> 0 | K9: =IF(RIGHT('Config #7'!B60,1)=")",195,0) -> 0 | L9: ='Config #7'!E67 -> 0
B10: Config #8 | C10: =IF(ISBLANK('Config #8'!B2),"",'Config #8'!B2) | D10: 0 | E10: ='Config #8'!E27 -> 0 | F10: =E10-O10 -> 0 | H10: 0 | I10: =IF('Config #8'!B55="Tandem (1st Position)",1317.19,0) -> 0 | J10: ='Config #8'!E63 -> 132 | K10: =IF(RIGHT('Config #8'!B60,1)=")",195,0) -> 0 | L10: ='Config #8'!E67 -> 16856.855
B11: Config #9 | C11: =IF(ISBLANK('Config #9'!B2),"",'Config #9'!B2) | D11: 0 | E11: ='Config #9'!E27 -> 0 | F11: =E11-O11 -> 0 | H11: 0 | I11: =IF('Config #9'!B55="Tandem (1st Position)",1317.19,0) -> 0 | J11: ='Config #9'!E63 -> 0 | K11: =IF(RIGHT('Config #9'!B60,1)=")",195,0) -> 0 | L11: ='Config #9'!E67 -> 0
B12: Config #10 | C12: =IF(ISBLANK('Config #10'!B2),"",'Config #10'!B2) | D12: 0 | E12: ='Config #10'!E27 -> 0 | F12: =E12-O12 -> 0 | H12: 0 | I12: =IF('Config #10'!B55="Tandem (1st Position)",1317.19,0) -> 0 | J12: ='Config #10'!E63 -> 0 | K12: =IF(RIGHT('Config #10'!B60,1)=")",195,0) -> 0 | L12: ='Config #10'!E67 -> 0
L14: Imagine Excel Total | M14: =SUM(E3:E12,L3:L12) -> 80179.376
L15: Ondal / Simeon Total | M15: =SUM(D3:D12,H3:K12) -> 591
L16: Delta Total | M16: =M14-M15 -> 79588.376
L17: Delta % | M17: =M16/M14 -> 0.99262903

Sheet Config #1
A1: CONFIGURATION #1 | B1: DESCRIPTION
A2: Configuration Name | B2: LED/FP (Patient Left): Camera Capable with Wall Control
A4: BOOM (SINGLE OR TANDEM) | B4: SELECTION | C4: IMAGINE LIST | D4: ONDAL LIST | E4: ONDAL COG | G4: HV Services | H4: Count | J4: Layer | K4: Selection | L4: FRONT | Q4: Selection | S4: Selection | T4: BACK | Y4: Selection | AE4: =COUNTIF(K5,"(2) Duplexes")+COUNTIF(Y5,"(2) Duplexes") -> 0 | AF4: =COUNTIF(Q5:S5,"(2) Duplexes") -> 0 | AG4: =COUNTIF(K5,"(3) Duplexes")+COUNTIF(Y5,"(3) Duplexes") -> 0 | AH4: =COUNTIF(Q5:S5,"(3) Duplexes") -> 0
A5: Model | B5: =IF(OR(ISBLANK(B8),ISBLANK(B9)),"",IF(ISBLANK(B9),0,(VLOOKUP(B9,'Ondal Booms'!B:F,5,FALSE)))&IF(ISBLANK(B8),0,(VLOOKUP(B8,'Ondal Booms'!B:F,5,FALSE)))) | C5: =IF(OR(ISBLANK(B5),B5=""),0,VLOOKUP(B5,'Ondal Booms'!B:G,4,FALSE)) -> 0 | D5: =IF(OR(ISBLANK(B5),B5=""),0,VLOOKUP(B5,'Ondal Booms'!B:G,2,FALSE)) -> 0 | E5: =IF(OR(ISBLANK(B5),B5=""),0,VLOOKUP(B5,'Ondal Booms'!B:G,3,FALSE)) -> 0 | G5: Duplex Count | H5: =COUNTIF(K5:Y14,"(2) Duplexes")*2+COUNTIF(K5:Y14,"(3) Duplexes")*3 -> 0 | J5: 1 Left | Z5: =15-COUNTIFS(K5:Y5,"") -> 0
A6: Ceiling Cover | C6: =IF(OR(ISBLANK(B6),B6=""),0,VLOOKUP(B6,'Ondal Booms'!B:G,4,FALSE)) -> 0 | D6: =IF(OR(ISBLANK(B6),B6=""),0,VLOOKUP(B6,'Ondal Booms'!B:G,2,FALSE)) -> 0 | E6: =IF(OR(ISBLANK(B6),B6=""),0,VLOOKUP(B6,'Ondal Booms'!B:G,3,FALSE)) -> 0 | J6: 1 Right | Z6: =15-COUNTIFS(K6:Y6,"") -> 0 | AE6: =COUNTIF(K7,"(2) Duplexes")+COUNTIF(Y7,"(2) Duplexes") -> 0 | AF6: =COUNTIF(Q7:S7,"(2) Duplexes") -> 0 | AG6: =COUNTIF(K7,"(3) Duplexes")+COUNTIF(Y7,"(3) Duplexes") -> 0 | AH6: =COUNTIF(Q7:S7,"(3) Duplexes") -> 0
A7: Ceiling Flange | C7: =IF(OR(ISBLANK(B7),B7=""),0,VLOOKUP(B7,'Ondal Booms'!B:G,4,FALSE)) -> 0 | D7: =IF(OR(ISBLANK(B7),B7=""),0,VLOOKUP(B7,'Ondal Booms'!B:G,2,FALSE)) -> 0 | E7: =IF(OR(ISBLANK(B7),B7=""),0,VLOOKUP(B7,'Ondal Booms'!B:G,3,FALSE)) -> 0 | G7: LV Services | H7: Count | J7: 2 Left | Z7: =15-COUNTIFS(K7:Y7,"") -> 0
A8: Top Arm | C8: =IF(OR(ISBLANK(B8),B8=""),0,VLOOKUP(B8,'Ondal Booms'!B:G,4,FALSE)) -> 0 | D8: =IF(OR(ISBLANK(B8),B8=""),0,VLOOKUP(B8,'Ondal Booms'!B:G,2,FALSE)) -> 0 | E8: =IF(OR(ISBLANK(B8),B8=""),0,VLOOKUP(B8,'Ondal Booms'!B:G,3,FALSE)) -> 0 | G8: Data Count | H8: =(COUNTIF(K5:Y14,"Data")) -> 0 | J8: 2 Right | Z8: =15-COUNTIFS(K8:Y8,"") -> 0 | AE8: =COUNTIF(K9,"(2) Duplexes")+COUNTIF(Y9,"(2) Duplexes") -> 0 | AF8: =COUNTIF(Q9:S9,"(2) Duplexes") -> 0 | AG8: =COUNTIF(K9,"(3) Duplexes")+COUNTIF(Y9,"(3) Duplexes") -> 0 | AH8: =COUNTIF(Q9:S9,"(3) Duplexes") -> 0
A9: Bottom Arm | C9: =IF(OR(ISBLANK(B9),B9=""),0,VLOOKUP(B9,'Ondal Booms'!B:G,4,FALSE)) -> 0 | D9: =IF(OR(ISBLANK(B9),B9=""),0,VLOOKUP(B9,'Ondal Booms'!B:G,2,FALSE)) -> 0 | E9: =IF(OR(ISBLANK(B9),B9=""),0,VLOOKUP(B9,'Ondal Booms'!B:G,3,FALSE)) -> 0 | G9: Storz 4in1 Count | H9: =(COUNTIF(K5:Y14,"Storz 4in1")) -> 0 | J9: 3 Left | Z9: =15-COUNTIFS(K9:Y9,"") -> 0
A10: Column Tube | C10: =IF(OR(ISBLANK(B10),B10=""),0,VLOOKUP(B10,'Ondal Booms'!B:G,4,FALSE)) -> 0 | D10: =IF(OR(ISBLANK(B10),B10=""),0,VLOOKUP(B10,'Ondal Booms'!B:G,2,FALSE)) -> 0 | E10: =IF(OR(ISBLANK(B10),B10=""),0,VLOOKUP(B10,'Ondal Booms'!B:G,3,FALSE)) -> 0 | J10: 3 Right | Z10: =15-COUNTIFS(K10:Y10,"") -> 0 | AE10: =COUNTIF(K11,"(2) Duplexes")+COUNTIF(Y11,"(2) Duplexes") -> 0 | AF10: =COUNTIF(Q11:S11,"(2) Duplexes") -> 0 | AG10: =COUNTIF(K11,"(3) Duplexes")+COUNTIF(Y11,"(3) Duplexes") -> 0 | AH10: =COUNTIF(Q11:S11,"(3) Duplexes") -> 0
A11: Service Head | C11: =IF(OR(ISBLANK(B11),B11=""),0,VLOOKUP(B11,'Ondal Booms'!B:G,4,FALSE)) -> 0 | D11: =IF(OR(ISBLANK(B11),B11=""),0,VLOOKUP(B11,'Ondal Booms'!B:G,2,FALSE)) -> 0 | E11: =IF(OR(ISBLANK(B11),B11=""),0,VLOOKUP(B11,'Ondal Booms'!B:G,3,FALSE)) -> 0 | G11: Medical Gases | H11: Count | J11: 4 Left | Z11: =15-COUNTIFS(K11:Y11,"") -> 0
A12: Electrical | B12: =IF(OR(H5=0,ISBLANK(H5)),"",H5&" Duplexes") | C12: =IF(OR(ISBLANK(B12),B12=""),0,VLOOKUP(B12,'Ondal Booms'!B:G,4,FALSE)) -> 0 | D12: =IF(OR(ISBLANK(B12),B12=""),0,VLOOKUP(B12,'Ondal Booms'!B:G,2,FALSE)) -> 0 | E12: =IF(OR(ISBLANK(B12),B12=""),0,VLOOKUP(B12,'Ondal Booms'!B:G,3,FALSE)) -> 0 | G12: Oxygen Count | H12: =(COUNTIF(K5:Y14,"Oxygen")) -> 0 | J12: 4 Right | Z12: =15-COUNTIFS(K12:Y12,"") -> 0 | AE12: =COUNTIF(K13,"(2) Duplexes")+COUNTIF(Y13,"(2) Duplexes") -> 0 | AF12: =COUNTIF(Q13:S13,"(2) Duplexes") -> 0 | AG12: =COUNTIF(K13,"(3) Duplexes")+COUNTIF(Y13,"(3) Duplexes") -> 0 | AH12: =COUNTIF(Q13:S13,"(3) Duplexes") -> 0
A13: Medical Gas | B13: =IF(OR(SUM(H12:H18)=0,ISBLANK(SUM(H12:H18))),"",SUM(H12:H18)&" Outlets") | C13: =IF(OR(ISBLANK(B13),B13=""),0,VLOOKUP(B13,'Ondal Booms'!B:G,4,FALSE)) -> 0 | D13: =IF(OR(ISBLANK(B13),B13=""),0,VLOOKUP(B13,'Ondal Booms'!B:G,2,FALSE)) -> 0 | E13: =IF(OR(ISBLANK(B13),B13=""),0,VLOOKUP(B13,'Ondal Booms'!B:G,3,FALSE)) -> 0 | G13: Med Air Count | H13: =COUNTIF(K5:Y14,"Medical Air") -> 0 | J13: 5 Left | Z13: =15-COUNTIFS(K13:Y13,"") -> 0
A14: # of Outlet Circuits | C14: =IF(OR(ISBLANK(B14),B14=""),0,VLOOKUP(B14,'Ondal Booms'!B:G,4,FALSE)) -> 0 | D14: =IF(OR(ISBLANK(B14),B14=""),0,VLOOKUP(B14,'Ondal Booms'!B:G,2,FALSE)) -> 0 | E14: =IF(OR(ISBLANK(B14),B14=""),0,VLOOKUP(B14,'Ondal Booms'!B:G,3,FALSE)) -> 0 | G14: Nitrous Count | H14: =COUNTIF(K5:Y14,"Nitrous Oxide") -> 0 | J14: 5 Right | Z14: =15-COUNTIFS(K14:Y14,"") -> 0
A15: Shelf (500mm) | C15: =IF(OR(ISBLANK(B15),B15=""),0,VLOOKUP(B15,'Ondal Booms'!B:G,4,FALSE)) -> 0 | D15: =IF(OR(ISBLANK(B15),B15=""),0,VLOOKUP(B15,'Ondal Booms'!B:G,2,FALSE)) -> 0 | E15: =IF(OR(ISBLANK(B15),B15=""),0,VLOOKUP(B15,'Ondal Booms'!B:G,3,FALSE)) -> 0 | G15: WAGD Count | H15: =COUNTIF(K5:Y14,"WAGD") -> 0
A16: Shelf (750mm) | C16: =IF(OR(ISBLANK(B16),B16=""),0,VLOOKUP(B16,'Ondal Booms'!B:G,4,FALSE)) -> 0 | D16: =IF(OR(ISBLANK(B16),B16=""),0,VLOOKUP(B16,'Ondal Booms'!B:G,2,FALSE)) -> 0 | E16: =IF(OR(ISBLANK(B16),B16=""),0,VLOOKUP(B16,'Ondal Booms'!B:G,3,FALSE)) -> 0 | G16: Vacuum Count | H16: =COUNTIF(K5:Y14,"Vacuum") -> 0
A17: Accessory 1 | C17: =IF(OR(ISBLANK(B17),B17=""),0,VLOOKUP(B17,'Ondal Booms'!B:G,4,FALSE)) -> 0 | D17: =IF(OR(ISBLANK(B17),B17=""),0,VLOOKUP(B17,'Ondal Booms'!B:G,2,FALSE)) -> 0 | E17: =IF(OR(ISBLANK(B17),B17=""),0,VLOOKUP(B17,'Ondal Booms'!B:G,3,FALSE)) -> 0 | G17: Nitrogen Count | H17: =COUNTIF(K5:Y14,"Nitrogen") -> 0
A18: Accessory 2 | C18: =IF(OR(ISBLANK(B18),B18=""),0,VLOOKUP(B18,'Ondal Booms'!B:G,4,FALSE)) -> 0 | D18: =IF(OR(ISBLANK(B18),B18=""),0,VLOOKUP(B18,'Ondal Booms'!B:G,2,FALSE)) -> 0 | E18: =IF(OR(ISBLANK(B18),B18=""),0,VLOOKUP(B18,'Ondal Booms'!B:G,3,FALSE)) -> 0 | G18: CO2 Count | H18: =COUNTIF(K5:Y14,"Carbon Dioxide") -> 0
A19: Accessory 3 | C19: =IF(OR(ISBLANK(B19),B19=""),0,VLOOKUP(B19,'Ondal Booms'!B:G,4,FALSE)) -> 0 | D19: =IF(OR(ISBLANK(B19),B19=""),0,VLOOKUP(B19,'Ondal Booms'!B:G,2,FALSE)) -> 0 | E19: =IF(OR(ISBLANK(B19),B19=""),0,VLOOKUP(B19,'Ondal Booms'!B:G,3,FALSE)) -> 0
A20: Accessory 4 | C20: =IF(OR(ISBLANK(B20),B20=""),0,VLOOKUP(B20,'Ondal Booms'!B:G,4,FALSE)) -> 0 | D20: =IF(OR(ISBLANK(B20),B20=""),0,VLOOKUP(B20,'Ondal Booms'!B:G,2,FALSE)) -> 0 | E20: =IF(OR(ISBLANK(B20),B20=""),0,VLOOKUP(B20,'Ondal Booms'!B:G,3,FALSE)) -> 0
A21: Accessory 5 | C21: =IF(OR(ISBLANK(B21),B21=""),0,VLOOKUP(B21,'Ondal Booms'!B:G,4,FALSE)) -> 0 | D21: =IF(OR(ISBLANK(B21),B21=""),0,VLOOKUP(B21,'Ondal Booms'!B:G,2,FALSE)) -> 0 | E21: =IF(OR(ISBLANK(B21),B21=""),0,VLOOKUP(B21,'Ondal Booms'!B:G,3,FALSE)) -> 0
A22: Accessory 6 | C22: =IF(OR(ISBLANK(B22),B22=""),0,VLOOKUP(B22,'Ondal Booms'!B:G,4,FALSE)) -> 0 | D22: =IF(OR(ISBLANK(B22),B22=""),0,VLOOKUP(B22,'Ondal Booms'!B:G,2,FALSE)) -> 0 | E22: =IF(OR(ISBLANK(B22),B22=""),0,VLOOKUP(B22,'Ondal Booms'!B:G,3,FALSE)) -> 0
A23: Accessory 7 | C23: =IF(OR(ISBLANK(B23),B23=""),0,VLOOKUP(B23,'Ondal Booms'!B:G,4,FALSE)) -> 0 | D23: =IF(OR(ISBLANK(B23),B23=""),0,VLOOKUP(B23,'Ondal Booms'!B:G,2,FALSE)) -> 0 | E23: =IF(OR(ISBLANK(B23),B23=""),0,VLOOKUP(B23,'Ondal Booms'!B:G,3,FALSE)) -> 0
A25: Errors? | B25: =IF(OR(ISBLANK(B5),B5=""),"", IF(OR(AND(B11="200mm Service Head",SUM(Z7:Z14)>0),AND(B11="400mm Service Head",SUM(Z9:Z14)>0),AND(B11="600mm Service Head",SUM(Z11:Z14)>0),AND(B11="800mm Service Head",SUM(Z13:Z14)>0)),"Select Longer Service Head or Remove Services", IF(AND(RIGHT(B9,2)="XL",RIGHT(B8,2)<>"XL"),"BOTTOM XL ARM REQUIRES TOP XL ARM", IF(OR(ISBLANK(B6),ISBLANK(B7),ISBLANK(B8),ISBLANK(B9),ISBLANK(B10),ISBLANK(B11),ISBLANK(B15),ISBLANK(B16),ISBLANK(B14)),"Missing Selections for Configuration", IF(AND(B11="Large Monitor Carrier",B9<>"Spring Articulating"),"Large Monitor Requires Spring Bottom Arm", IF(OR(AND(RIGHT(B7,2)="XL",RIGHT(B8,2)<>"XL"),AND(RIGHT(B8,2)="XL",RIGHT(B7,2)<>"XL")),"Both Top Arm and Ceiling Flange Must Be XL", IF(COUNTIF(AE4:AH12,1)>1,"Mismatch Electrical Configuration", "")))))) )
C26: IMAGINE LIST | D26: ONDAL LIST | E26: ONDAL SALES
A27: Equipment List Price | B27: =IF(OR(B6="",ISBLANK(B6)),"NO CONFIGURATION SELECTED",C27) -> NO CONFIGURATION SELECTED | C27: =SUM(C5:C23) -> 0 | D27: =SUM(D5:D23) -> 0 | E27: =SUM(E5:E23) -> 0 | J27: ="<-- EXPAND TO SHOW OPTIONS / SERVICE HEAD" -> <-- EXPAND TO SHOW OPTIONS / SERVICE HEAD
AE28: =COUNTIF(K30,"(2) Duplexes")+COUNTIF(Y30,"(2) Duplexes") -> 0 | AF28: =COUNTIF(Q30:S30,"(2) Duplexes") -> 0 | AG28: =COUNTIF(K30,"(3) Duplexes")+COUNTIF(Y30,"(3) Duplexes") -> 0 | AH28: =COUNTIF(Q30:S30,"(3) Duplexes") -> 0
A29: BOOM (TANDEM 2ND ONLY) | B29: SELECTION | C29: IMAGINE LIST | D29: ONDAL LIST | E29: ONDAL COG | G29: HV Services | H29: Count | J29: Layer | K29: Selection | L29: FRONT | Q29: Selection | S29: Selection | T29: BACK | Y29: Selection
A30: Model | B30: =IF(OR(ISBLANK(B32),ISBLANK(B33)),"",IF(ISBLANK(B33),0,(VLOOKUP(B33,'Ondal Booms'!B:F,5,FALSE)))&IF(ISBLANK(B32),0,(VLOOKUP(B32,'Ondal Booms'!B:F,5,FALSE)))) | C30: =IF(OR(ISBLANK(B30),B30=""),0,VLOOKUP(B30,'Ondal Booms'!B:G,4,FALSE)) -> 0 | D30: =IF(OR(ISBLANK(B30),B30=""),0,VLOOKUP(B30,'Ondal Booms'!B:G,2,FALSE)) -> 0 | E30: =IF(OR(ISBLANK(B30),B30=""),0,VLOOKUP(B30,'Ondal Booms'!B:G,3,FALSE)) -> 0 | G30: Duplex Count | H30: =COUNTIF(K30:Y39,"(2) Duplexes")*2+COUNTIF(K30:Y39,"(3) Duplexes")*3 -> 0 | J30: 1 Left | Z30: =15-COUNTIFS(K30:Y30,"") -> 0
A31: Ceiling Flange | C31: =IF(OR(ISBLANK(B31),B31=""),0,VLOOKUP(B31,'Ondal Booms'!B:G,4,FALSE)) -> 0 | D31: =IF(OR(ISBLANK(B31),B31=""),0,VLOOKUP(B31,'Ondal Booms'!B:G,2,FALSE)) -> 0 | E31: =IF(OR(ISBLANK(B31),B31=""),0,VLOOKUP(B31,'Ondal Booms'!B:G,3,FALSE)) -> 0 | G31: LV Services | H31: Count | J31: 1 Right | Z31: =15-COUNTIFS(K31:Y31,"") -> 0 | AE31: =COUNTIF(K32,"(2) Duplexes")+COUNTIF(Y32,"(2) Duplexes") -> 0 | AF31: =COUNTIF(Q32:S32,"(2) Duplexes") -> 0 | AG31: =COUNTIF(K32,"(3) Duplexes")+COUNTIF(Y32,"(3) Duplexes") -> 0 | AH31: =COUNTIF(Q32:S32,"(3) Duplexes") -> 0
A32: Top Arm | C32: =IF(OR(ISBLANK(B32),B32=""),0,VLOOKUP(B32,'Ondal Booms'!B:G,4,FALSE)) -> 0 | D32: =IF(OR(ISBLANK(B32),B32=""),0,VLOOKUP(B32,'Ondal Booms'!B:G,2,FALSE)) -> 0 | E32: =IF(OR(ISBLANK(B32),B32=""),0,VLOOKUP(B32,'Ondal Booms'!B:G,3,FALSE)) -> 0 | G32: Data Count | H32: =(COUNTIF(K30:Y39,"Data")) -> 0 | J32: 2 Left | Z32: =15-COUNTIFS(K32:Y32,"") -> 0
A33: Bottom Arm | C33: =IF(OR(ISBLANK(B33),B33=""),0,VLOOKUP(B33,'Ondal Booms'!B:G,4,FALSE)) -> 0 | D33: =IF(OR(ISBLANK(B33),B33=""),0,VLOOKUP(B33,'Ondal Booms'!B:G,2,FALSE)) -> 0 | E33: =IF(OR(ISBLANK(B33),B33=""),0,VLOOKUP(B33,'Ondal Booms'!B:G,3,FALSE)) -> 0 | G33: Storz 4in1 Count | H33: =(COUNTIF(K30:Y39,"Storz 4in1")) -> 0 | J33: 2 Right | Z33: =15-COUNTIFS(K33:Y33,"") -> 0 | AE33: =COUNTIF(K34,"(2) Duplexes")+COUNTIF(Y34,"(2) Duplexes") -> 0 | AF33: =COUNTIF(Q34:S34,"(2) Duplexes") -> 0 | AG33: =COUNTIF(K34,"(3) Duplexes")+COUNTIF(Y34,"(3) Duplexes") -> 0 | AH33: =COUNTIF(Q34:S34,"(3) Duplexes") -> 0
A34: Column Tube | C34: =IF(OR(ISBLANK(B34),B34=""),0,VLOOKUP(B34,'Ondal Booms'!B:G,4,FALSE)) -> 0 | D34: =IF(OR(ISBLANK(B34),B34=""),0,VLOOKUP(B34,'Ondal Booms'!B:G,2,FALSE)) -> 0 | E34: =IF(OR(ISBLANK(B34),B34=""),0,VLOOKUP(B34,'Ondal Booms'!B:G,3,FALSE)) -> 0 | J34: 3 Left | Z34: =15-COUNTIFS(K34:Y34,"") -> 0
A35: Service Head | C35: =IF(OR(ISBLANK(B35),B35=""),0,VLOOKUP(B35,'Ondal Booms'!B:G,4,FALSE)) -> 0 | D35: =IF(OR(ISBLANK(B35),B35=""),0,VLOOKUP(B35,'Ondal Booms'!B:G,2,FALSE)) -> 0 | E35: =IF(OR(ISBLANK(B35),B35=""),0,VLOOKUP(B35,'Ondal Booms'!B:G,3,FALSE)) -> 0 | G35: Medical Gases | H35: Count | J35: 3 Right | Z35: =15-COUNTIFS(K35:Y35,"") -> 0 | AE35: =COUNTIF(K36,"(2) Duplexes")+COUNTIF(Y36,"(2) Duplexes") -> 0 | AF35: =COUNTIF(Q36:S36,"(2) Duplexes") -> 0 | AG35: =COUNTIF(K36,"(3) Duplexes")+COUNTIF(Y36,"(3) Duplexes") -> 0 | AH35: =COUNTIF(Q36:S36,"(3) Duplexes") -> 0
A36: Electrical | B36: =IF(OR(H30=0,ISBLANK(H30)),"",H30&" Duplexes") | C36: =IF(OR(ISBLANK(B36),B36=""),0,VLOOKUP(B36,'Ondal Booms'!B:G,4,FALSE)) -> 0 | D36: =IF(OR(ISBLANK(B36),B36=""),0,VLOOKUP(B36,'Ondal Booms'!B:G,2,FALSE)) -> 0 | E36: =IF(OR(ISBLANK(B36),B36=""),0,VLOOKUP(B36,'Ondal Booms'!B:G,3,FALSE)) -> 0 | G36: Oxygen Count | H36: =(COUNTIF(K30:Y39,"Oxygen")) -> 0 | J36: 4 Left | Z36: =15-COUNTIFS(K36:Y36,"") -> 0
A37: Medical Gas | B37: =IF(OR(SUM(H36:H42)=0,ISBLANK(SUM(H36:H42))),"",SUM(H36:H42)&" Outlets") | C37: =IF(OR(ISBLANK(B37),B37=""),0,VLOOKUP(B37,'Ondal Booms'!B:G,4,FALSE)) -> 0 | D37: =IF(OR(ISBLANK(B37),B37=""),0,VLOOKUP(B37,'Ondal Booms'!B:G,2,FALSE)) -> 0 | E37: =IF(OR(ISBLANK(B37),B37=""),0,VLOOKUP(B37,'Ondal Booms'!B:G,3,FALSE)) -> 0 | G37: Med Air Count | H37: =COUNTIF(K30:Y39,"Medical Air") -> 0 | J37: 4 Right | Z37: =15-COUNTIFS(K37:Y37,"") -> 0 | AE37: =COUNTIF(K38,"(2) Duplexes")+COUNTIF(Y38,"(2) Duplexes") -> 0 | AF37: =COUNTIF(Q38:S38,"(2) Duplexes") -> 0 | AG37: =COUNTIF(K38,"(3) Duplexes")+COUNTIF(Y38,"(3) Duplexes") -> 0 | AH37: =COUNTIF(Q38:S38,"(3) Duplexes") -> 0
A38: # of Outlet Circuits | C38: =IF(OR(ISBLANK(B38),B38=""),0,VLOOKUP(B38,'Ondal Booms'!B:G,4,FALSE)) -> 0 | D38: =IF(OR(ISBLANK(B38),B38=""),0,VLOOKUP(B38,'Ondal Booms'!B:G,2,FALSE)) -> 0 | E38: =IF(OR(ISBLANK(B38),B38=""),0,VLOOKUP(B38,'Ondal Booms'!B:G,3,FALSE)) -> 0 | G38: Nitrous Count | H38: =COUNTIF(K30:Y39,"Nitrous Oxide") -> 0 | J38: 5 Left | Z38: =15-COUNTIFS(K38:Y38,"") -> 0
A39: Shelf (500mm) | C39: =IF(OR(ISBLANK(B39),B39=""),0,VLOOKUP(B39,'Ondal Booms'!B:G,4,FALSE)) -> 0 | D39: =IF(OR(ISBLANK(B39),B39=""),0,VLOOKUP(B39,'Ondal Booms'!B:G,2,FALSE)) -> 0 | E39: =IF(OR(ISBLANK(B39),B39=""),0,VLOOKUP(B39,'Ondal Booms'!B:G,3,FALSE)) -> 0 | G39: WAGD Count | H39: =COUNTIF(K30:Y39,"WAGD") -> 0 | J39: 5 Right | Z39: =15-COUNTIFS(K39:Y39,"") -> 0
A40: Shelf (750mm) | C40: =IF(OR(ISBLANK(B40),B40=""),0,VLOOKUP(B40,'Ondal Booms'!B:G,4,FALSE)) -> 0 | D40: =IF(OR(ISBLANK(B40),B40=""),0,VLOOKUP(B40,'Ondal Booms'!B:G,2,FALSE)) -> 0 | E40: =IF(OR(ISBLANK(B40),B40=""),0,VLOOKUP(B40,'Ondal Booms'!B:G,3,FALSE)) -> 0 | G40: Vacuum Count | H40: =COUNTIF(K30:Y39,"Vacuum") -> 0
A41: Accessory 1 | C41: =IF(OR(ISBLANK(B41),B41=""),0,VLOOKUP(B41,'Ondal Booms'!B:G,4,FALSE)) -> 0 | D41: =IF(OR(ISBLANK(B41),B41=""),0,VLOOKUP(B41,'Ondal Booms'!B:G,2,FALSE)) -> 0 | E41: =IF(OR(ISBLANK(B41),B41=""),0,VLOOKUP(B41,'Ondal Booms'!B:G,3,FALSE)) -> 0 | G41: Nitrogen Count | H41: =COUNTIF(K30:Y39,"Nitrogen") -> 0
A42: Accessory 2 | C42: =IF(OR(ISBLANK(B42),B42=""),0,VLOOKUP(B42,'Ondal Booms'!B:G,4,FALSE)) -> 0 | D42: =IF(OR(ISBLANK(B42),B42=""),0,VLOOKUP(B42,'Ondal Booms'!B:G,2,FALSE)) -> 0 | E42: =IF(OR(ISBLANK(B42),B42=""),0,VLOOKUP(B42,'Ondal Booms'!B:G,3,FALSE)) -> 0 | G42: CO2 Count | H42: =COUNTIF(K30:Y39,"Carbon Dioxide") -> 0
...

Sheet Config #2
A1: CONFIGURATION #2 | B1: DESCRIPTION
A2: Configuration Name | B2: LED/FP (Patient Right)
A4: BOOM (SINGLE OR TANDEM) | B4: SELECTION | C4: IMAGINE LIST | D4: ONDAL LIST | E4: ONDAL COG | G4: HV Services | H4: Count | J4: Layer | K4: Selection | L4: FRONT | Q4: Selection | S4: Selection | T4: BACK | Y4: Selection | AE4: =COUNTIF(K5,"(2) Duplexes")+COUNTIF(Y5,"(2) Duplexes") -> 0 | AF4: =COUNTIF(Q5:S5,"(2) Duplexes") -> 0 | AG4: =COUNTIF(K5,"(3) Duplexes")+COUNTIF(Y5,"(3) Duplexes") -> 0 | AH4: =COUNTIF(Q5:S5,"(3) Duplexes") -> 0
A5: Model | B5: =IF(OR(ISBLANK(B8),ISBLANK(B9)),"",IF(ISBLANK(B9),0,(VLOOKUP(B9,'Ondal Booms'!B:F,5,FALSE)))&IF(ISBLANK(B8),0,(VLOOKUP(B8,'Ondal Booms'!B:F,5,FALSE)))) | C5: =IF(OR(ISBLANK(B5),B5=""),0,VLOOKUP(B5,'Ondal Booms'!B:G,4,FALSE)) -> 0 | D5: =IF(OR(ISBLANK(B5),B5=""),0,VLOOKUP(B5,'Ondal Booms'!B:G,2,FALSE)) -> 0 | E5: =IF(OR(ISBLANK(B5),B5=""),0,VLOOKUP(B5,'Ondal Booms'!B:G,3,FALSE)) -> 0 | G5: Duplex Count | H5: =COUNTIF(K5:Y14,"(2) Duplexes")*2+COUNTIF(K5:Y14,"(3) Duplexes")*3 -> 0 | J5: 1 Left | Z5: =15-COUNTIFS(K5:Y5,"") -> 0
A6: Ceiling Cover | C6: =IF(OR(ISBLANK(B6),B6=""),0,VLOOKUP(B6,'Ondal Booms'!B:G,4,FALSE)) -> 0 | D6: =IF(OR(ISBLANK(B6),B6=""),0,VLOOKUP(B6,'Ondal Booms'!B:G,2,FALSE)) -> 0 | E6: =IF(OR(ISBLANK(B6),B6=""),0,VLOOKUP(B6,'Ondal Booms'!B:G,3,FALSE)) -> 0 | J6: 1 Right | Z6: =15-COUNTIFS(K6:Y6,"") -> 0 | AE6: =COUNTIF(K7,"(2) Duplexes")+COUNTIF(Y7,"(2) Duplexes") -> 0 | AF6: =COUNTIF(Q7:S7,"(2) Duplexes") -> 0 | AG6: =COUNTIF(K7,"(3) Duplexes")+COUNTIF(Y7,"(3) Duplexes") -> 0 | AH6: =COUNTIF(Q7:S7,"(3) Duplexes") -> 0
A7: Ceiling Flange | C7: =IF(OR(ISBLANK(B7),B7=""),0,VLOOKUP(B7,'Ondal Booms'!B:G,4,FALSE)) -> 0 | D7: =IF(OR(ISBLANK(B7),B7=""),0,VLOOKUP(B7,'Ondal Booms'!B:G,2,FALSE)) -> 0 | E7: =IF(OR(ISBLANK(B7),B7=""),0,VLOOKUP(B7,'Ondal Booms'!B:G,3,FALSE)) -> 0 | G7: LV Services | H7: Count | J7: 2 Left | Z7: =15-COUNTIFS(K7:Y7,"") -> 0
A8: Top Arm | C8: =IF(OR(ISBLANK(B8),B8=""),0,VLOOKUP(B8,'Ondal Booms'!B:G,4,FALSE)) -> 0 | D8: =IF(OR(ISBLANK(B8),B8=""),0,VLOOKUP(B8,'Ondal Booms'!B:G,2,FALSE)) -> 0 | E8: =IF(OR(ISBLANK(B8),B8=""),0,VLOOKUP(B8,'Ondal Booms'!B:G,3,FALSE)) -> 0 | G8: Data Count | H8: =(COUNTIF(K5:Y14,"Data")) -> 0 | J8: 2 Right | Z8: =15-COUNTIFS(K8:Y8,"") -> 0 | AE8: =COUNTIF(K9,"(2) Duplexes")+COUNTIF(Y9,"(2) Duplexes") -> 0 | AF8: =COUNTIF(Q9:S9,"(2) Duplexes") -> 0 | AG8: =COUNTIF(K9,"(3) Duplexes")+COUNTIF(Y9,"(3) Duplexes") -> 0 | AH8: =COUNTIF(Q9:S9,"(3) Duplexes") -> 0
A9: Bottom Arm | C9: =IF(OR(ISBLANK(B9),B9=""),0,VLOOKUP(B9,'Ondal Booms'!B:G,4,FALSE)) -> 0 | D9: =IF(OR(ISBLANK(B9),B9=""),0,VLOOKUP(B9,'Ondal Booms'!B:G,2,FALSE)) -> 0 | E9: =IF(OR(ISBLANK(B9),B9=""),0,VLOOKUP(B9,'Ondal Booms'!B:G,3,FALSE)) -> 0 | G9: Storz 4in1 Count | H9: =(COUNTIF(K5:Y14,"Storz 4in1")) -> 0 | J9: 3 Left | Z9: =15-COUNTIFS(K9:Y9,"") -> 0
A10: Column Tube | C10: =IF(OR(ISBLANK(B10),B10=""),0,VLOOKUP(B10,'Ondal Booms'!B:G,4,FALSE)) -> 0 | D10: =IF(OR(ISBLANK(B10),B10=""),0,VLOOKUP(B10,'Ondal Booms'!B:G,2,FALSE)) -> 0 | E10: =IF(OR(ISBLANK(B10),B10=""),0,VLOOKUP(B10,'Ondal Booms'!B:G,3,FALSE)) -> 0 | J10: 3 Right | Z10: =15-COUNTIFS(K10:Y10,"") -> 0 | AE10: =COUNTIF(K11,"(2) Duplexes")+COUNTIF(Y11,"(2) Duplexes") -> 0 | AF10: =COUNTIF(Q11:S11,"(2) Duplexes") -> 0 | AG10: =COUNTIF(K11,"(3) Duplexes")+COUNTIF(Y11,"(3) Duplexes") -> 0 | AH10: =COUNTIF(Q11:S11,"(3) Duplexes") -> 0
A11: Service Head | C11: =IF(OR(ISBLANK(B11),B11=""),0,VLOOKUP(B11,'Ondal Booms'!B:G,4,FALSE)) -> 0 | D11: =IF(OR(ISBLANK(B11),B11=""),0,VLOOKUP(B11,'Ondal Booms'!B:G,2,FALSE)) -> 0 | E11: =IF(OR(ISBLANK(B11),B11=""),0,VLOOKUP(B11,'Ondal Booms'!B:G,3,FALSE)) -> 0 | G11: Medical Gases | H11: Count | J11: 4 Left | Z11: =15-COUNTIFS(K11:Y11,"") -> 0
A12: Electrical | B12: =IF(OR(H5=0,ISBLANK(H5)),"",H5&" Duplexes") | C12: =IF(OR(ISBLANK(B12),B12=""),0,VLOOKUP(B12,'Ondal Booms'!B:G,4,FALSE)) -> 0 | D12: =IF(OR(ISBLANK(B12),B12=""),0,VLOOKUP(B12,'Ondal Booms'!B:G,2,FALSE)) -> 0 | E12: =IF(OR(ISBLANK(B12),B12=""),0,VLOOKUP(B12,'Ondal Booms'!B:G,3,FALSE)) -> 0 | G12: Oxygen Count | H12: =(COUNTIF(K5:Y14,"Oxygen")) -> 0 | J12: 4 Right | Z12: =15-COUNTIFS(K12:Y12,"") -> 0 | AE12: =COUNTIF(K13,"(2) Duplexes")+COUNTIF(Y13,"(2) Duplexes") -> 0 | AF12: =COUNTIF(Q13:S13,"(2) Duplexes") -> 0 | AG12: =COUNTIF(K13,"(3) Duplexes")+COUNTIF(Y13,"(3) Duplexes") -> 0 | AH12: =COUNTIF(Q13:S13,"(3) Duplexes") -> 0
A13: Medical Gas | B13: =IF(OR(SUM(H12:H18)=0,ISBLANK(SUM(H12:H18))),"",SUM(H12:H18)&" Outlets") | C13: =IF(OR(ISBLANK(B13),B13=""),0,VLOOKUP(B13,'Ondal Booms'!B:G,4,FALSE)) -> 0 | D13: =IF(OR(ISBLANK(B13),B13=""),0,VLOOKUP(B13,'Ondal Booms'!B:G,2,FALSE)) -> 0 | E13: =IF(OR(ISBLANK(B13),B13=""),0,VLOOKUP(B13,'Ondal Booms'!B:G,3,FALSE)) -> 0 | G13: Med Air Count | H13: =COUNTIF(K5:Y14,"Medical Air") -> 0 | J13: 5 Left | Z13: =15-COUNTIFS(K13:Y13,"") -> 0
A14: # of Outlet Circuits | C14: =IF(OR(ISBLANK(B14),B14=""),0,VLOOKUP(B14,'Ondal Booms'!B:G,4,FALSE)) -> 0 | D14: =IF(OR(ISBLANK(B14),B14=""),0,VLOOKUP(B14,'Ondal Booms'!B:G,2,FALSE)) -> 0 | E14: =IF(OR(ISBLANK(B14),B14=""),0,VLOOKUP(B14,'Ondal Booms'!B:G,3,FALSE)) -> 0 | G14: Nitrous Count | H14: =COUNTIF(K5:Y14,"Nitrous Oxide") -> 0 | J14: 5 Right | Z14: =15-COUNTIFS(K14:Y14,"") -> 0
A15: Shelf (500mm) | C15: =IF(OR(ISBLANK(B15),B15=""),0,VLOOKUP(B15,'Ondal Booms'!B:G,4,FALSE)) -> 0 | D15: =IF(OR(ISBLANK(B15),B15=""),0,VLOOKUP(B15,'Ondal Booms'!B:G,2,FALSE)) -> 0 | E15: =IF(OR(ISBLANK(B15),B15=""),0,VLOOKUP(B15,'Ondal Booms'!B:G,3,FALSE)) -> 0 | G15: WAGD Count | H15: =COUNTIF(K5:Y14,"WAGD") -> 0
A16: Shelf (750mm) | C16: =IF(OR(ISBLANK(B16),B16=""),0,VLOOKUP(B16,'Ondal Booms'!B:G,4,FALSE)) -> 0 | D16: =IF(OR(ISBLANK(B16),B16=""),0,VLOOKUP(B16,'Ondal Booms'!B:G,2,FALSE)) -> 0 | E16: =IF(OR(ISBLANK(B16),B16=""),0,VLOOKUP(B16,'Ondal Booms'!B:G,3,FALSE)) -> 0 | G16: Vacuum Count | H16: =COUNTIF(K5:Y14,"Vacuum") -> 0
A17: Accessory 1 | C17: =IF(OR(ISBLANK(B17),B17=""),0,VLOOKUP(B17,'Ondal Booms'!B:G,4,FALSE)) -> 0 | D17: =IF(OR(ISBLANK(B17),B17=""),0,VLOOKUP(B17,'Ondal Booms'!B:G,2,FALSE)) -> 0 | E17: =IF(OR(ISBLANK(B17),B17=""),0,VLOOKUP(B17,'Ondal Booms'!B:G,3,FALSE)) -> 0 | G17: Nitrogen Count | H17: =COUNTIF(K5:Y14,"Nitrogen") -> 0
A18: Accessory 2 | C18: =IF(OR(ISBLANK(B18),B18=""),0,VLOOKUP(B18,'Ondal Booms'!B:G,4,FALSE)) -> 0 | D18: =IF(OR(ISBLANK(B18),B18=""),0,VLOOKUP(B18,'Ondal Booms'!B:G,2,FALSE)) -> 0 | E18: =IF(OR(ISBLANK(B18),B18=""),0,VLOOKUP(B18,'Ondal Booms'!B:G,3,FALSE)) -> 0 | G18: CO2 Count | H18: =COUNTIF(K5:Y14,"Carbon Dioxide") -> 0
A19: Accessory 3 | C19: =IF(OR(ISBLANK(B19),B19=""),0,VLOOKUP(B19,'Ondal Booms'!B:G,4,FALSE)) -> 0 | D19: =IF(OR(ISBLANK(B19),B19=""),0,VLOOKUP(B19,'Ondal Booms'!B:G,2,FALSE)) -> 0 | E19: =IF(OR(ISBLANK(B19),B19=""),0,VLOOKUP(B19,'Ondal Booms'!B:G,3,FALSE)) -> 0
A20: Accessory 4 | C20: =IF(OR(ISBLANK(B20),B20=""),0,VLOOKUP(B20,'Ondal Booms'!B:G,4,FALSE)) -> 0 | D20: =IF(OR(ISBLANK(B20),B20=""),0,VLOOKUP(B20,'Ondal Booms'!B:G,2,FALSE)) -> 0 | E20: =IF(OR(ISBLANK(B20),B20=""),0,VLOOKUP(B20,'Ondal Booms'!B:G,3,FALSE)) -> 0
A21: Accessory 5 | C21: =IF(OR(ISBLANK(B21),B21=""),0,VLOOKUP(B21,'Ondal Booms'!B:G,4,FALSE)) -> 0 | D21: =IF(OR(ISBLANK(B21),B21=""),0,VLOOKUP(B21,'Ondal Booms'!B:G,2,FALSE)) -> 0 | E21: =IF(OR(ISBLANK(B21),B21=""),0,VLOOKUP(B21,'Ondal Booms'!B:G,3,FALSE)) -> 0
A22: Accessory 6 | C22: =IF(OR(ISBLANK(B22),B22=""),0,VLOOKUP(B22,'Ondal Booms'!B:G,4,FALSE)) -> 0 | D22: =IF(OR(ISBLANK(B22),B22=""),0,VLOOKUP(B22,'Ondal Booms'!B:G,2,FALSE)) -> 0 | E22: =IF(OR(ISBLANK(B22),B22=""),0,VLOOKUP(B22,'Ondal Booms'!B:G,3,FALSE)) -> 0
A23: Accessory 7 | C23: =IF(OR(ISBLANK(B23),B23=""),0,VLOOKUP(B23,'Ondal Booms'!B:G,4,FALSE)) -> 0 | D23: =IF(OR(ISBLANK(B23),B23=""),0,VLOOKUP(B23,'Ondal Booms'!B:G,2,FALSE)) -> 0 | E23: =IF(OR(ISBLANK(B23),B23=""),0,VLOOKUP(B23,'Ondal Booms'!B:G,3,FALSE)) -> 0
A25: Errors? | B25: =IF(OR(ISBLANK(B5),B5=""),"", IF(OR(AND(B11="200mm Service Head",SUM(Z7:Z14)>0),AND(B11="400mm Service Head",SUM(Z9:Z14)>0),AND(B11="600mm Service Head",SUM(Z11:Z14)>0),AND(B11="800mm Service Head",SUM(Z13:Z14)>0)),"Select Longer Service Head or Remove Services", IF(AND(RIGHT(B9,2)="XL",RIGHT(B8,2)<>"XL"),"BOTTOM XL ARM REQUIRES TOP XL ARM", IF(OR(ISBLANK(B6),ISBLANK(B7),ISBLANK(B8),ISBLANK(B9),ISBLANK(B10),ISBLANK(B11),ISBLANK(B15),ISBLANK(B16),ISBLANK(B14)),"Missing Selections for Configuration", IF(AND(B11="Large Monitor Carrier",B9<>"Spring Articulating"),"Large Monitor Requires Spring Bottom Arm", IF(OR(AND(RIGHT(B7,2)="XL",RIGHT(B8,2)<>"XL"),AND(RIGHT(B8,2)="XL",RIGHT(B7,2)<>"XL")),"Both Top Arm and Ceiling Flange Must Be XL", IF(COUNTIF(AE4:AH12,1)>1,"Mismatch Electrical Configuration", "")))))) )
C26: IMAGINE LIST | D26: ONDAL LIST | E26: ONDAL SALES
A27: Equipment List Price | B27: =IF(OR(B6="",ISBLANK(B6)),"NO CONFIGURATION SELECTED",C27) -> NO CONFIGURATION SELECTED | C27: =SUM(C5:C23) -> 0 | D27: =SUM(D5:D23) -> 0 | E27: =SUM(E5:E23) -> 0 | J27: ="<-- EXPAND TO SHOW OPTIONS / SERVICE HEAD" -> <-- EXPAND TO SHOW OPTIONS / SERVICE HEAD
AE28: =COUNTIF(K30,"(2) Duplexes")+COUNTIF(Y30,"(2) Duplexes") -> 0 | AF28: =COUNTIF(Q30:S30,"(2) Duplexes") -> 0 | AG28: =COUNTIF(K30,"(3) Duplexes")+COUNTIF(Y30,"(3) Duplexes") -> 0 | AH28: =COUNTIF(Q30:S30,"(3) Duplexes") -> 0
