Workbook

Sheet 3D Compatible Boom Pricing
A1: Part Number | B1: Configuration | D1: Imagine List Price | E1: Imagine Sales Price | K1: Boom Options | U1: Ceiling Flange (E)
A2: 211-101-001 | B2: Powered Boom, Top Arm 600mm, SH 200mm | D2: 32984.453 | E2: 16492.227 | G2: Sections | H2: Part Number | J2: Boom Discount | L2: Model (A) | M2: Service Head | U2: for standard models
A3: 211-102-001 | B3: Powered Boom, Top Arm 800mm, SH 200mm | D3: 32984.453 | E3: 16492.227 | G3: Powered Model | H3: 211-XXX-XXX | J3: 0.5 | K3: Standard Top Arm | L3: Powered | N3: 600 | O3: 800 | P3: 1000 | Q3: 1200 | R3: 1400 | S3: 1600 | U3: 100mm | V3: 0 | Y3: Key | AC3: Price Increase | AD3: 600 | AE3: 800 | AF3: 1000 | AG3: 1200 | AH3: 1400 | AI3: 1600
A4: 211-103-001 | B4: Powered Boom, Top Arm 1000mm, SH 200mm | D4: 32984.453 | E4: 16492.227 | G4: Spring Model | H4: 212-XXX-XXX | K4: Powered Bottom Arm | L4: 35398.8 | M4: 200 | N4: 35398.8 | O4: 35398.8 | P4: 35398.8 | Q4: 35398.8 | R4: na | S4: na | U4: 300mm | V4: 251.81 | Y4: Model | AA4: A | AC4: 200 | AH4: 1591.55 | AI4: 3291.97
A5: 211-104-001 | B5: Powered Boom, Top Arm 1200mm, SH 200mm | D5: 32984.453 | E5: 16492.227 | G5: Fixed Model | H5: 213-XXX-XXX | K5: (articulating - 1000mm) | M5: 400 | N5: 37373.71 | O5: 37373.71 | P5: 37373.71 | Q5: 37373.71 | R5: na | S5: na | U5: 500mm | V5: 493.73 | Y5: Service Head Length | AA5: B | AC5: 400 | AD5: 1974.91 | AE5: 1974.91 | AF5: 1974.91 | AG5: 1974.91 | AH5: 3566.86 | AI5: 5266.88
A6: 211-101-002 | B6: Powered Boom, Top Arm 600mm, SH 400mm | D6: 34959.36 | E6: 17479.68 | G6: Large Monitor Mount | H6: 212-XXX-XXX-301 | M6: 600 | N6: 39353.55 | O6: 39353.55 | P6: 39353.55 | Q6: 39353.55 | R6: na | S6: na | U6: for XL+ models | Y6: Top Arm Length | AC6: 600 | AD6: 3954.75 | AE6: 3954.75 | AF6: 3954.75 | AG6: 3954.75 | AH6: 5546.3 | AI6: 7246.72
A7: 211-102-002 | B7: Powered Boom, Top Arm 800mm, SH 400mm | D7: 34959.36 | E7: 17479.68 | G7: Top Arm (600mm-1200mm) | H7: XXX-101-XXX (etc) | M7: 800 | N7: 41392.67 | O7: 41392.67 | P7: 41392.67 | Q7: 41392.67 | R7: na | S7: na | U7: 100mm | V7: 0 | Y7: Ceiling Flange | AA7: D | AC7: 800 | AD7: 5993.87 | AE7: 5993.87 | AF7: 5993.87 | AG7: 5993.87 | AH7: 7585.42 | AI7: 9285.84
A8: 211-103-002 | B8: Powered Boom, Top Arm 1000mm, SH 400mm | D8: 34959.36 | E8: 17479.68 | G8: XL Top Arm | H8: XXX-111-XXX (etc) | M8: 1000 | N8: 43426.83 | O8: 43426.83 | P8: 43426.83 | Q8: 43426.83 | R8: na | S8: na | U8: 300mm | V8: 508.53 | Y8: Optional Services | AA8: C | AC8: 1000 | AD8: 8028.03 | AE8: 8028.03 | AF8: 8028.03 | AG8: 8028.03 | AH8: 9619.58 | AI8: 11320
A9: 211-104-002 | B9: Powered Boom, Top Arm 1200mm, SH 400mm | D9: 34959.36 | E9: 17479.68 | G9: XL Bottom Arm | H9: XXX-XXX-101-XXX (etc) | U9: 500mm | V9: 1214.59 | Y9: Light Options | AA9: E
A10: 211-101-003 | B10: Powered Boom, Top Arm 600mm, SH 600mm | D10: 36939.2 | E10: 18469.6 | G10: Service Head (200mm - 1000mm) | H10: XXX-XXX-001 (etc) | K10: XL Top Arm | L10: Powered XL | N10: 600 | O10: 800 | P10: 1000 | Q10: 1200 | R10: 1400 | S10: 1600 | Y10: Optional Light Accessories | AA10: F
A11: 211-102-003 | B11: Powered Boom, Top Arm 800mm, SH 600mm | D11: 36939.2 | E11: 18469.6 | G11: Accessories | H11: 600-XXX | K11: Powered Bottom Arm | L11: 39326.43 | M11: 200 | N11: 39326.43 | O11: 39326.43 | P11: 39326.43 | Q11: 39326.43 | R11: 40917.98 | S11: 42618.4 | Y11: Not in the Tool
A12: 211-103-003 | B12: Powered Boom, Top Arm 1000mm, SH 600mm | D12: 36939.2 | E12: 18469.6 | K12: (articulating - 1000mm) | M12: 400 | N12: 41301.34 | O12: 41301.34 | P12: 41301.34 | Q12: 41301.34 | R12: 42893.29 | S12: 44593.31 | U12: Services / Accessories (D - if applicable) | W12: optional
A13: 211-104-003 | B13: Powered Boom, Top Arm 1200mm, SH 600mm | D13: 36939.2 | E13: 18469.6 | M13: 600 | N13: 43281.18 | O13: 43281.18 | P13: 43281.18 | Q13: 43281.18 | R13: 44872.73 | S13: 46573.15 | U13: Med-Gas | V13: 790 | W13: per gas addition | Y13: Total Price = A + B + C + D + E + F
A14: 211-101-004 | B14: Powered Boom, Top Arm 600mm, SH 800mm | D14: 38978.32 | E14: 19489.16 | M14: 800 | N14: 45320.3 | O14: 45320.3 | P14: 45320.3 | Q14: 45320.3 | R14: 46911.85 | S14: 48612.27 | U14: Electrical (2 duplexes) | V14: 543.12 | W14: per layer
A15: 211-102-004 | B15: Powered Boom, Top Arm 800mm, SH 800mm | D15: 38978.32 | E15: 19489.16 | G15: Shipping & Installation | M15: 1000 | N15: 47354.46 | O15: 47354.46 | P15: 47354.46 | Q15: 47354.46 | R15: 48946.01 | S15: 50646.43 | U15: Electrical (3 duplexes) | V15: 997.33 | W15: per layer
A16: 211-103-004 | B16: Powered Boom, Top Arm 1000mm, SH 800mm | D16: 38978.32 | E16: 19489.16 | U16: Data | V16: 0
A17: 211-104-004 | B17: Powered Boom, Top Arm 1200mm, SH 800mm | D17: 38978.32 | E17: 19489.16 | K17: Standard Top Arm | L17: Spring | N17: 600 | O17: 800 | P17: 1000 | Q17: 1200 | R17: 1400 | S17: 1600 | U17: Nitrogen Regulator | V17: 2105.92 | W17: per boom
A18: 211-101-005 | B18: Powered Boom, Top Arm 600mm, SH 1000mm | D18: 41012.48 | E18: 20506.24 | K18: Spring Bottom Arm | L18: 33594.72 | M18: 200 | N18: 33594.72 | O18: 33594.72 | P18: 33594.72 | Q18: 33594.72 | R18: na | S18: na | U18: Data Pass thru | V18: 770.21333 | W18: per boom
A19: 211-102-005 | B19: Powered Boom, Top Arm 800mm, SH 1000mm | D19: 41012.48 | E19: 20506.24 | K19: (articulating - 1000mm) | M19: 400 | N19: 35569.63 | O19: 35569.63 | P19: 35569.63 | Q19: 35569.63 | R19: na | S19: na | U19: Tandem Mount with 1 future boom option | V19: 3393.2067 | W19: per mount
A20: 211-103-005 | B20: Powered Boom, Top Arm 1000mm, SH 1000mm | D20: 41012.48 | E20: 20506.24 | M20: 600 | N20: 37549.47 | O20: 37549.47 | P20: 37549.47 | Q20: 37549.47 | R20: na | S20: na | U20: Rails
A21: 211-104-005 | B21: Powered Boom, Top Arm 1200mm, SH 1000mm | D21: 41012.48 | E21: 20506.24 | M21: 800 | N21: 39588.59 | O21: 39588.59 | P21: 39588.59 | Q21: 39588.59 | R21: na | S21: na | U21: Shelfs | V21: 1344.6222 | W21: per shelf
M22: 1000 | N22: 41622.75 | O22: 41622.75 | P22: 41622.75 | Q22: 41622.75 | R22: na | S22: na
A23: 211-111-001 | B23: Powered Boom, XL Top Arm 600mm, SH 200mm | D23: 36912.08 | E23: 18456.04
A24: 211-112-001 | B24: Powered Boom, XL Top Arm 800mm, SH 200mm | D24: 36912.08 | E24: 18456.04 | K24: XL Top Arm | L24: Spring XL | N24: 600 | O24: 800 | P24: 1000 | Q24: 1200 | R24: 1400 | S24: 1600
A25: 211-113-001 | B25: Powered Boom, XL Top Arm 1000mm, SH 200mm | D25: 36912.08 | E25: 18456.04 | K25: Spring Bottom Arm | L25: 38315.52 | M25: 200 | N25: 38315.52 | O25: 38315.52 | P25: 38315.52 | Q25: 38315.52 | R25: 39907.07 | S25: 41607.49
A26: 211-114-001 | B26: Powered Boom, XL Top Arm 1200mm, SH 200mm | D26: 36912.08 | E26: 18456.04 | K26: (articulating - 1000mm) | M26: 400 | N26: 40290.43 | O26: 40290.43 | P26: 40290.43 | Q26: 40290.43 | R26: 41882.38 | S26: 43582.4
A27: 211-115-001 | B27: Powered Boom, XL Top Arm 1400mm, SH 200mm | D27: 38503.627 | E27: 19251.813 | M27: 600 | N27: 42270.27 | O27: 42270.27 | P27: 42270.27 | Q27: 42270.27 | R27: 43861.82 | S27: 45562.24
A28: 211-116-001 | B28: Powered Boom, XL Top Arm 1600mm, SH 200mm | D28: 40204.053 | E28: 20102.027 | M28: 800 | N28: 44309.39 | O28: 44309.39 | P28: 44309.39 | Q28: 44309.39 | R28: 45900.94 | S28: 47601.36
A29: 211-111-002 | B29: Powered Boom, XL Top Arm 600mm, SH 400mm | D29: 38886.987 | E29: 19443.493 | M29: 1000 | N29: 46343.55 | O29: 46343.55 | P29: 46343.55 | Q29: 46343.55 | R29: 47935.1 | S29: 49635.52
A30: 211-112-002 | B30: Powered Boom, XL Top Arm 800mm, SH 400mm | D30: 38886.987 | E30: 19443.493
A31: 211-113-002 | B31: Powered Boom, XL Top Arm 1000mm, SH 400mm | D31: 38886.987 | E31: 19443.493 | K31: Standard Top Arm | L31: Fixed | N31: 600 | O31: 800 | P31: 1000 | Q31: 1200 | R31: 1400 | S31: 1600 | U31: Incorporate "sales price" and discounted List price
A32: 211-114-002 | B32: Powered Boom, XL Top Arm 1200mm, SH 400mm | D32: 38886.987 | E32: 19443.493 | K32: Standard Fixeed Arm (1000mm) | L32: 23781.02 | M32: 200 | N32: 23781.02 | O32: 23781.02 | P32: 23781.02 | Q32: 23781.02 | R32: na | S32: na
A33: 211-115-002 | B33: Powered Boom, XL Top Arm 1400mm, SH 400mm | D33: 40478.533 | E33: 20239.267 | M33: 400 | N33: 25755.93 | O33: 25755.93 | P33: 25755.93 | Q33: 25755.93 | R33: na | S33: na
A34: 211-116-002 | B34: Powered Boom, XL Top Arm 1600mm, SH 400mm | D34: 42178.96 | E34: 21089.48 | M34: 600 | N34: 27735.77 | O34: 27735.77 | P34: 27735.77 | Q34: 27735.77 | R34: na | S34: na
A35: 211-111-003 | B35: Powered Boom, XL Top Arm 600mm, SH 600mm | D35: 40866.827 | E35: 20433.413 | M35: 800 | N35: 29774.89 | O35: 29774.89 | P35: 29774.89 | Q35: 29774.89 | R35: na | S35: na
A36: 211-112-003 | B36: Powered Boom, XL Top Arm 800mm, SH 600mm | D36: 40866.827 | E36: 20433.413 | M36: 1000 | N36: 31809.05 | O36: 31809.05 | P36: 31809.05 | Q36: 31809.05 | R36: na | S36: na
A37: 211-113-003 | B37: Powered Boom, XL Top Arm 1000mm, SH 600mm | D37: 40866.827 | E37: 20433.413
A38: 211-114-003 | B38: Powered Boom, XL Top Arm 1200mm, SH 600mm | D38: 40866.827 | E38: 20433.413 | K38: XL Top Arm | L38: Fixed XL | N38: 600 | O38: 800 | P38: 1000 | Q38: 1200 | R38: 1400 | S38: 1600
A39: 211-115-003 | B39: Powered Boom, XL Top Arm 1400mm, SH 600mm | D39: 42458.373 | E39: 21229.187 | K39: Standard Fixeed Arm (1000mm) | L39: 27382.03 | M39: 200 | N39: 27382.03 | O39: 27382.03 | P39: 27382.03 | Q39: 27382.03 | R39: 28973.58 | S39: 30674
A40: 211-116-003 | B40: Powered Boom, XL Top Arm 1600mm, SH 600mm | D40: 44158.8 | E40: 22079.4 | M40: 400 | N40: 29356.94 | O40: 29356.94 | P40: 29356.94 | Q40: 29356.94 | R40: 30948.89 | S40: 32648.91
...

Sheet 3D Compatible Light Pricing
A1: Part Number | B1: Configuration | C1: Current 3D Tool Config (Top to bottom) | D1: Imagine List Price | E1: Imagine Sales Price | G1: Sections | H1: Part Number
A2: 111-001111 | B2: 7000 - LED | C2: U|ONE | D2: 37407.7 | E2: =D2*$H$11 -> 18703.85 | G2: 7000/ U|ONE Lights and all variations | H2: 111
A3: 111-001112 | B3: 7000 - LED / LED | C3: U|ONE, U|ONE | D3: 73942.55 | E3: =D3*$H$11 -> 36971.275 | G3: No light configs (not including booms) | H3: 112
A4: 111-001113 | B4: 7000 - LED / LED / LED | C4: U|ONE, U|ONE, U|ONE | D4: 106014.52 | E4: =D4*$H$11 -> 53007.258 | G4: 8000/ U|002 Lights and all variations | H4: 113
A5: 111-001114 | B5: 7000 - LED / FP | C5: U|ONE, Flat Panel | D5: 54751.183 | E5: =D5*$H$11 -> 27375.592 | G5: Sim.Flex | H5: 114
A6: 111-001115 | B6: 7000 - FP / LED | C6: Flat Panel, U|ONE | D6: 54376.533 | E6: =D6*$H$11 -> 27188.267 | G6: Drop Down Options | H6: 115
A7: 111-001116 | B7: 7000 - LED / LED / FP | C7: U|ONE, U|ONE, Flat Panel | D7: 89254.35 | E7: =D7*$H$11 -> 44627.175 | G7: Light Exchange | H7: 116
A8: 111-001117 | B8: 7000 - LED / LS | C8: U|ONE, Lead Shield | D8: 63174.183 | E8: =D8*$H$11 -> 31587.092 | G8: Shipping & Installation | H8: 117
A9: 111-001118 | B9: 7000 - LED / LED / LS | C9: U|ONE, U|ONE, Lead Shield | D9: 95246.15 | E9: =D9*$H$11 -> 47623.075
A10: 111-001119 | B10: 7000 LC - LED | C10: U|ONE (Low Ceiling) | D10: 39936.433 | E10: =D10*$H$11 -> 19968.217 | H10: Light Discount
A11: 111-001120 | B11: 7000 LC - LED / LED | C11: U|ONE (Low Ceiling), U|ONE (Low Ceiling) | D11: 79000.017 | E11: =D11*$H$11 -> 39500.008 | H11: 0.5
A12: 111-001121 | B12: 7000 LC - LED / LED / LED | C12: U|ONE (Low Ceiling), U|ONE (Low Ceiling), U|ONE (Low Ceiling) | D12: 113600.72 | E12: =D12*$H$11 -> 56800.358
A13: 111-001122 | B13: 7000 LC - LED / FP | C13: U|ONE (Low Ceiling), Flat Panel | D13: 57279.917 | E13: =D13*$H$11 -> 28639.958
A14: 111-001123 | B14: 7000 LC - FP / LED | C14: Flat Panel, U|ONE (Low Ceiling) | D14: 56905.267 | E14: =D14*$H$11 -> 28452.633
A15: 111-001124 | B15: 7000 LC - LED / LED / FP | C15: U|ONE (Low Ceiling), U|ONE (Low Ceiling), Flat Panel | D15: 94311.817 | E15: =D15*$H$11 -> 47155.908
A16: 111-001125 | B16: 7000 LC - LED / LS | C16: U|ONE (Low Ceiling), Lead Sheild | D16: 65702.917 | E16: =D16*$H$11 -> 32851.458
A17: 111-001126 | B17: 7000 LC - LED / LED / LS | C17: U|ONE (Low Ceiling), U|ONE (Low Ceiling), Lead Sheild | D17: 100303.62 | E17: =D17*$H$11 -> 50151.808
A18: 112-001111 | B18: No Lights - FP | C18: Flat Panel | D18: 20611 | E18: =D18*$H$11 -> 10305.5
A19: 112-001112 | B19: No Lights - LS | C19: Lead Sheild | D19: 26639.333 | E19: =D19*$H$11 -> 13319.667
A20: 112-001113 | B20: No Lights - FP / FP | C20: Flat Panel, Flat Panel | D20: 38481.933 | E20: =D20*$H$11 -> 19240.967
A21: 112-001114 | B21: No Lights - LS / LS | C21: Lead Sheild, Lead Sheild | D21: 52405.817 | E21: =D21*$H$11 -> 26202.908
A22: 112-001115 | B22: No Lights - FP / LS | C22: Flat Panel, Lead Sheild | D22: 43608.167 | E22: =D22*$H$11 -> 21804.083
A23: 112-001116 | B23: No Lights - LS / FP | C23: Lead Sheild, Flat Panel | D23: 43982.817 | E23: =D23*$H$11 -> 21991.408
... A56: 113-001126 | B56: Future Light LC - LED / LED / LS | C56: U|003 LC , U|003 LC , Lead Sheild | D56: 0 | E56: =D56*$H$11 -> 0
A59: Additional Model Options (Price should be assigned to sim.flex models in addition to model price) | D59: Imagine List Price | E59: Imagine Sales Price
A60: 114-001111 | B60: Sim.Flex (1 Arm) | C60: Assign when sim.flex option is selected (with 1 arm) | D60: 5833.3333 | E60: =D60*$H$11 -> 2916.6667
A61: 114-001112 | B61: Sim.Flex (2 Arms) | C61: Assign when sim.flex option is selected (with 2 arms) | D61: 9166.6667 | E61: =D61*$H$11 -> 4583.3333
A62: 114-001113 | B62: Sim.Flex (3 Arms) | C62: Assign when sim.flex option is selected (with 3 arms) | D62: 12500 | E62: =D62*$H$11 -> 6250
E63: =D63*$H$11 -> 0
A64: Additional Options (Drop Down) | G64: Example
A65: Part Number | B65: Option | D65: Imagine List Price | E65: Imagine Sales Price | G65: Light Single / Tandem | H65: Options
B66: Ceiling Cover | G66: Ceiling Cover
A67: 115-001111 | B67: Single Light (Standard) | D67: 1563.2167 | E67: =D67*$H$11 -> 781.60833 | G67: Wall Control
A68: 115-001112 | B68: Single Light (Universal) | D68: 3398.9667 | E68: =D68*$H$11 -> 1699.4833 | G68: Integration Control
A69: 115-001113 | B69: Tandem (1st Position) | D69: 5807.6533 | E69: =D69*$H$11 -> 2903.8267 | G69: In-Light Camera
A70: 115-001114 | B70: Tandem (2nd Position) | D70: 0 | E70: =D70*$H$11 -> 0 | G70: Disposable Adpaters
B71: Wall Control
B72: Wall Control in Seperate Config | D72: 0 | E72: =D72*$H$11 -> 0
A73: 115-001115 | B73: Wall Control (Single) | D73: 4710.4167 | E73: =D73*$H$11 -> 2355.2083
A74: 115-001116 | B74: Wall Control (Dual) | D74: 2146.85 | E74: =D74*$H$11 -> 1073.425
...

Sheet 2025_03_28 3D Boom Pricing
A1: Part Number | B1: Configuration | D1: Imagine List Price | E1: Imagine Sales Price | K1: Boom Options | U1: Ceiling Flange (E)
A2: 211-101-001 | B2: Powered Boom, Top Arm 600mm, SH 200mm | D2: ='2025_03_28 Boom Pricing'!$E$4+'2025_03_28 Boom Pricing'!$E$23+'2025_03_28 Boom Pricing'!$E$38+'2025_03_28 Boom Pricing'!$E$46 -> 32984.453 | E2: =D2*(1-0.5) -> 16492.227 | G2: Sections | H2: Part Number | J2: Boom Discount | L2: Model (A) | M2: Service Head | U2: for standard models
A3: 211-102-001 | B3: Powered Boom, Top Arm 800mm, SH 200mm | D3: ='2025_03_28 Boom Pricing'!$E$4+'2025_03_28 Boom Pricing'!$E$23+'2025_03_28 Boom Pricing'!$E$39+'2025_03_28 Boom Pricing'!$E$46 -> 32984.453 | E3: =D3*(1-0.5) -> 16492.227 | G3: Powered Model | H3: 211-XXX-XXX | J3: 0.5 | K3: Standard Top Arm | L3: Powered | N3: 600 | O3: 800 | P3: 1000 | Q3: 1200 | R3: 1400 | S3: 1600 | U3: 100mm | V3: 0 | Y3: Key | AC3: Price Increase | AD3: 600 | AE3: 800 | AF3: 1000 | AG3: 1200 | AH3: 1400 | AI3: 1600
A4: 211-103-001 | B4: Powered Boom, Top Arm 1000mm, SH 200mm | D4: ='2025_03_28 Boom Pricing'!$E$4+'2025_03_28 Boom Pricing'!$E$23+'2025_03_28 Boom Pricing'!$E$40+'2025_03_28 Boom Pricing'!$E$46 -> 32984.453 | E4: =D4*(1-0.5) -> 16492.227 | G4: Spring Model | H4: 212-XXX-XXX | K4: Powered Bottom Arm | L4: 35398.8 | M4: 200 | N4: =SUM($L$4+AD4) -> 35398.8 | O4: =SUM($L$4+AE4) -> 35398.8 | P4: =SUM($L$4+AF4) -> 35398.8 | Q4: =SUM($L$4+AG4) -> 35398.8 | R4: na | S4: na | U4: 300mm | V4: 251.81 | Y4: Model | AA4: A | AC4: 200 | AH4: 1591.55 | AI4: 3291.97
A5: 211-104-001 | B5: Powered Boom, Top Arm 1200mm, SH 200mm | D5: ='2025_03_28 Boom Pricing'!$E$4+'2025_03_28 Boom Pricing'!$E$23+'2025_03_28 Boom Pricing'!$E$41+'2025_03_28 Boom Pricing'!$E$46 -> 32984.453 | E5: =D5*(1-0.5) -> 16492.227 | G5: Fixed Model | H5: 213-XXX-XXX | K5: (articulating - 1000mm) | M5: 400 | N5: =SUM($L$4+AD5) -> 37373.71 | O5: =SUM($L$4+AE5) -> 37373.71 | P5: =SUM($L$4+AF5) -> 37373.71 | Q5: =SUM($L$4+AG5) -> 37373.71 | R5: na | S5: na | U5: 500mm | V5: 493.73 | Y5: Service Head Length | AA5: B | AC5: 400 | AD5: 1974.91 | AE5: 1974.91 | AF5: 1974.91 | AG5: 1974.91 | AH5: =SUM(1974.91+1591.95) -> 3566.86 | AI5: =SUM(3291.97+1974.91) -> 5266.88
A6: 211-101-002 | B6: Powered Boom, Top Arm 600mm, SH 400mm | D6: ='2025_03_28 Boom Pricing'!$E$4+'2025_03_28 Boom Pricing'!$E$24+'2025_03_28 Boom Pricing'!$E$38+'2025_03_28 Boom Pricing'!$E$46 -> 34959.36 | E6: =D6*(1-0.5) -> 17479.68 | G6: Fixed XL Model | H6: 313- | M6: 600 | N6: =SUM($L$4+AD6) -> 39353.55 | O6: =SUM($L$4+AE6) -> 39353.55 | P6: =SUM($L$4+AF6) -> 39353.55 | Q6: =SUM($L$4+AG6) -> 39353.55 | R6: na | S6: na | U6: for XL+ models | Y6: Top Arm Length | AC6: 600 | AD6: 3954.75 | AE6: 3954.75 | AF6: 3954.75 | AG6: 3954.75 | AH6: =SUM(3954.75+1591.55) -> 5546.3 | AI6: =SUM(3291.97+3954.75) -> 7246.72
A7: 211-102-002 | B7: Powered Boom, Top Arm 800mm, SH 400mm | D7: ='2025_03_28 Boom Pricing'!$E$4+'2025_03_28 Boom Pricing'!$E$24+'2025_03_28 Boom Pricing'!$E$39+'2025_03_28 Boom Pricing'!$E$46 -> 34959.36 | E7: =D7*(1-0.5) -> 17479.68 | G7: Fixed XXL Model | H7: 413-XXX-XXX | M7: 800 | N7: =SUM($L$4+AD7) -> 41392.67 | O7: =SUM($L$4+AE7) -> 41392.67 | P7: =SUM($L$4+AF7) -> 41392.67 | Q7: =SUM($L$4+AG7) -> 41392.67 | R7: na | S7: na | U7: 100mm | V7: 0 | Y7: Ceiling Flange | AA7: D | AC7: 800 | AD7: 5993.87 | AE7: 5993.87 | AF7: 5993.87 | AG7: 5993.87 | AH7: =SUM(5993.87+1591.55) -> 7585.42 | AI7: =SUM(5993.87+3291.97) -> 9285.84
A8: 211-103-002 | B8: Powered Boom, Top Arm 1000mm, SH 400mm | D8: ='2025_03_28 Boom Pricing'!$E$4+'2025_03_28 Boom Pricing'!$E$24+'2025_03_28 Boom Pricing'!$E$40+'2025_03_28 Boom Pricing'!$E$46 -> 34959.36 | E8: =D8*(1-0.5) -> 17479.68 | G8: Top Arm (600mm-1200mm) | H8: XXX-101-XXX (etc) | M8: 1000 | N8: =SUM($L$4+AD8) -> 43426.83 | O8: =SUM($L$4+AE8) -> 43426.83 | P8: =SUM($L$4+AF8) -> 43426.83 | Q8: =SUM($L$4+AG8) -> 43426.83 | R8: na | S8: na | U8: 300mm | V8: 508.53 | Y8: Optional Services | AA8: C | AC8: 1000 | AD8: 8028.03 | AE8: 8028.03 | AF8: 8028.03 | AG8: 8028.03 | AH8: 9619.58 | AI8: 11320
A9: 211-104-002 | B9: Powered Boom, Top Arm 1200mm, SH 400mm | D9: ='2025_03_28 Boom Pricing'!$E$4+'2025_03_28 Boom Pricing'!$E$24+'2025_03_28 Boom Pricing'!$E$41+'2025_03_28 Boom Pricing'!$E$46 -> 34959.36 | E9: =D9*(1-0.5) -> 17479.68 | G9: XL Top Arm | H9: XXX-111-XXX (etc) | U9: 500mm | V9: 1214.59 | Y9: Light Options | AA9: E
A10: 211-101-003 | B10: Powered Boom, Top Arm 600mm, SH 600mm | D10: ='2025_03_28 Boom Pricing'!$E$4+'2025_03_28 Boom Pricing'!$E$25+'2025_03_28 Boom Pricing'!$E$38+'2025_03_28 Boom Pricing'!$E$46 -> 36939.2 | E10: =D10*(1-0.5) -> 18469.6 | G10: XL Bottom Arm | H10: XXX-XXX-101-XXX (etc) | K10: XL Top Arm | L10: Powered XL | N10: 600 | O10: 800 | P10: 1000 | Q10: 1200 | R10: 1400 | S10: 1600 | Y10: Optional Light Accessories | AA10: F
A11: 211-102-003 | B11: Powered Boom, Top Arm 800mm, SH 600mm | D11: ='2025_03_28 Boom Pricing'!$E$4+'2025_03_28 Boom Pricing'!$E$25+'2025_03_28 Boom Pricing'!$E$39+'2025_03_28 Boom Pricing'!$E$46 -> 36939.2 | E11: =D11*(1-0.5) -> 18469.6 | G11: Service Head (200mm - 1000mm) | H11: XXX-XXX-001 (etc) | K11: Powered Bottom Arm | L11: 39326.43 | M11: 200 | N11: =SUM($L$11+AD4) -> 39326.43 | O11: =SUM($L$11+AE4) -> 39326.43 | P11: =SUM($L$11+AF4) -> 39326.43 | Q11: =SUM($L$11+AG4) -> 39326.43 | R11: =SUM($L$11+AH4) -> 40917.98 | S11: =SUM($L$11+AI4) -> 42618.4 | Y11: Not in the Tool
A12: 211-103-003 | B12: Powered Boom, Top Arm 1000mm, SH 600mm | D12: ='2025_03_28 Boom Pricing'!$E$4+'2025_03_28 Boom Pricing'!$E$25+'2025_03_28 Boom Pricing'!$E$40+'2025_03_28 Boom Pricing'!$E$46 -> 36939.2 | E12: =D12*(1-0.5) -> 18469.6 | K12: (articulating - 1000mm) | M12: 400 | N12: =SUM($L$11+AD5) -> 41301.34 | O12: =SUM($L$11+AE5) -> 41301.34 | P12: =SUM($L$11+AF5) -> 41301.34 | Q12: =SUM($L$11+AG5) -> 41301.34 | R12: =SUM($L$11+AH5) -> 42893.29 | S12: =SUM($L$11+AI5) -> 44593.31 | U12: Services / Accessories (D - if applicable) | W12: optional
A13: 211-104-003 | B13: Powered Boom, Top Arm 1200mm, SH 600mm | D13: ='2025_03_28 Boom Pricing'!$E$4+'2025_03_28 Boom Pricing'!$E$25+'2025_03_28 Boom Pricing'!$E$41+'2025_03_28 Boom Pricing'!$E$46 -> 36939.2 | E13: =D13*(1-0.5) -> 18469.6 | M13: 600 | N13: =SUM($L$11+AD6) -> 43281.18 | O13: =SUM($L$11+AE6) -> 43281.18 | P13: =SUM($L$11+AF6) -> 43281.18 | Q13: =SUM($L$11+AG6) -> 43281.18 | R13: =SUM($L$11+AH6) -> 44872.73 | S13: =SUM($L$11+AI6) -> 46573.15 | U13: Med-Gas | V13: 790 | W13: per gas addition | Y13: Total Price = A + B + C + D + E + F
A14: 211-101-004 | B14: Powered Boom, Top Arm 600mm, SH 800mm | D14: ='2025_03_28 Boom Pricing'!$E$4+'2025_03_28 Boom Pricing'!$E$26+'2025_03_28 Boom Pricing'!$E$38+'2025_03_28 Boom Pricing'!$E$46 -> 38978.32 | E14: =D14*(1-0.5) -> 19489.16 | M14: 800 | N14: =SUM($L$11+AD7) -> 45320.3 | O14: =SUM($L$11+AE7) -> 45320.3 | P14: =SUM($L$11+AF7) -> 45320.3 | Q14: =SUM($L$11+AG7) -> 45320.3 | R14: =SUM($L$11+AH7) -> 46911.85 | S14: =SUM($L$11+AI7) -> 48612.27 | U14: Electrical (2 duplexes) | V14: 543.12 | W14: per layer
A15: 211-102-004 | B15: Powered Boom, Top Arm 800mm, SH 800mm | D15: ='2025_03_28 Boom Pricing'!$E$4+'2025_03_28 Boom Pricing'!$E$26+'2025_03_28 Boom Pricing'!$E$39+'2025_03_28 Boom Pricing'!$E$46 -> 38978.32 | E15: =D15*(1-0.5) -> 19489.16 | G15: Shipping & Installation | M15: 1000 | N15: =SUM($L$11+AD8) -> 47354.46 | O15: =SUM($L$11+AE8) -> 47354.46 | P15: =SUM($L$11+AF8) -> 47354.46 | Q15: =SUM($L$11+AG8) -> 47354.46 | R15: =SUM($L$11+AH8) -> 48946.01 | S15: =SUM($L$11+AI8) -> 50646.43 | U15: Electrical (3 duplexes) | V15: 997.33 | W15: per layer
A16: 211-103-004 | B16: Powered Boom, Top Arm 1000mm, SH 800mm | D16: ='2025_03_28 Boom Pricing'!$E$4+'2025_03_28 Boom Pricing'!$E$26+'2025_03_28 Boom Pricing'!$E$40+'2025_03_28 Boom Pricing'!$E$46 -> 38978.32 | E16: =D16*(1-0.5) -> 19489.16 | U16: Data | V16: 0
A17: 211-104-004 | B17: Powered Boom, Top Arm 1200mm, SH 800mm | D17: ='2025_03_28 Boom Pricing'!$E$4+'2025_03_28 Boom Pricing'!$E$26+'2025_03_28 Boom Pricing'!$E$41+'2025_03_28 Boom Pricing'!$E$46 -> 38978.32 | E17: =D17*(1-0.5) -> 19489.16 | K17: Standard Top Arm | L17: Spring | N17: 600 | O17: 800 | P17: 1000 | Q17: 1200 | R17: 1400 | S17: 1600 | U17: Nitrogen Regulator | V17: 2105.92 | W17: per boom
A18: 211-101-005 | B18: Powered Boom, Top Arm 600mm, SH 1000mm | D18: ='2025_03_28 Boom Pricing'!$E$4+'2025_03_28 Boom Pricing'!$E$27+'2025_03_28 Boom Pricing'!$E$38+'2025_03_28 Boom Pricing'!$E$46 -> 41012.48 | E18: =D18*(1-0.5) -> 20506.24 | K18: Spring Bottom Arm | L18: 33594.72 | M18: 200 | N18: =SUM($L$18+AD4) -> 33594.72 | O18: =SUM($L$18+AE4) -> 33594.72 | P18: =SUM($L$18+AF4) -> 33594.72 | Q18: =SUM($L$18+AG4) -> 33594.72 | R18: na | S18: na | U18: Data Pass thru | V18: 770.21333 | W18: per boom
A19: 211-102-005 | B19: Powered Boom, Top Arm 800mm, SH 1000mm | D19: ='2025_03_28 Boom Pricing'!$E$4+'2025_03_28 Boom Pricing'!$E$27+'2025_03_28 Boom Pricing'!$E$39+'2025_03_28 Boom Pricing'!$E$46 -> 41012.48 | E19: =D19*(1-0.5) -> 20506.24 | K19: (articulating - 1000mm) | M19: 400 | N19: =SUM($L$18+AD5) -> 35569.63 | O19: =SUM($L$18+AE5) -> 35569.63 | P19: =SUM($L$18+AF5) -> 35569.63 | Q19: =SUM($L$18+AG5) -> 35569.63 | R19: na | S19: na | U19: Tandem Mount with 1 future boom option | V19: 3393.2067 | W19: per mount
A20: 211-103-005 | B20: Powered Boom, Top Arm 1000mm, SH 1000mm | D20: ='2025_03_28 Boom Pricing'!$E$4+'2025_03_28 Boom Pricing'!$E$27+'2025_03_28 Boom Pricing'!$E$40+'2025_03_28 Boom Pricing'!$E$46 -> 41012.48 | E20: =D20*(1-0.5) -> 20506.24 | M20: 600 | N20: =SUM($L$18+AD6) -> 37549.47 | O20: =SUM($L$18+AE6) -> 37549.47 | P20: =SUM($L$18+AF6) -> 37549.47 | Q20: =SUM($L$18+AG6) -> 37549.47 | R20: na | S20: na | U20: Rails
A21: 211-104-005 | B21: Powered Boom, Top Arm 1200mm, SH 1000mm | D21: ='2025_03_28 Boom Pricing'!$E$4+'2025_03_28 Boom Pricing'!$E$27+'2025_03_28 Boom Pricing'!$E$41+'2025_03_28 Boom Pricing'!$E$46 -> 41012.48 | E21: =D21*(1-0.5) -> 20506.24 | M21: 800 | N21: =SUM($L$18+AD7) -> 39588.59 | O21: =SUM($L$18+AE7) -> 39588.59 | P21: =SUM($L$18+AF7) -> 39588.59 | Q21: =SUM($L$18+AG7) -> 39588.59 | R21: na | S21: na | U21: Shelfs | V21: 1344.6222 | W21: per shelf
M22: 1000 | N22: =SUM($L$18+AD8) -> 41622.75 | O22: =SUM($L$18+AE8) -> 41622.75 | P22: =SUM($L$18+AF8) -> 41622.75 | Q22: =SUM($L$18+AG8) -> 41622.75 | R22: na | S22: na
A23: 211-111-001 | B23: Powered Boom, XL Top Arm 600mm, SH 200mm | D23: ='2025_03_28 Boom Pricing'!$E$5+'2025_03_28 Boom Pricing'!$E$23+'2025_03_28 Boom Pricing'!$E$38+'2025_03_28 Boom Pricing'!$E$46 -> 36912.08 | E23: =D23*(1-0.5) -> 18456.04
A24: 211-112-001 | B24: Powered Boom, XL Top Arm 800mm, SH 200mm | D24: ='2025_03_28 Boom Pricing'!$E$5+'2025_03_28 Boom Pricing'!$E$23+'2025_03_28 Boom Pricing'!$E$39+'2025_03_28 Boom Pricing'!$E$46 -> 36912.08 | E24: =D24*(1-0.5) -> 18456.04 | K24: XL Top Arm | L24: Spring XL | N24: 600 | O24: 800 | P24: 1000 | Q24: 1200 | R24: 1400 | S24: 1600
A25: 211-113-001 | B25: Powered Boom, XL Top Arm 1000mm, SH 200mm | D25: ='2025_03_28 Boom Pricing'!$E$5+'2025_03_28 Boom Pricing'!$E$23+'2025_03_28 Boom Pricing'!$E$40+'2025_03_28 Boom Pricing'!$E$46 -> 36912.08 | E25: =D25*(1-0.5) -> 18456.04 | K25: Spring Bottom Arm | L25: 38315.52 | M25: 200 | N25: =SUM($L$25+AD4) -> 38315.52 | O25: =SUM($L$25+AE4) -> 38315.52 | P25: =SUM($L$25+AF4) -> 38315.52 | Q25: =SUM($L$25+AG4) -> 38315.52 | R25: =SUM($L$25+AH4) -> 39907.07 | S25: =SUM($L$25+AI4) -> 41607.49
A26: 211-114-001 | B26: Powered Boom, XL Top Arm 1200mm, SH 200mm | D26: ='2025_03_28 Boom Pricing'!$E$5+'2025_03_28 Boom Pricing'!$E$23+'2025_03_28 Boom Pricing'!$E$41+'2025_03_28 Boom Pricing'!$E$46 -> 36912.08 | E26: =D26*(1-0.5) -> 18456.04 | K26: (articulating - 1000mm) | M26: 400 | N26: =SUM($L$25+AD5) -> 40290.43 | O26: =SUM($L$25+AE5) -> 40290.43 | P26: =SUM($L$25+AF5) -> 40290.43 | Q26: =SUM($L$25+AG5) -> 40290.43 | R26: =SUM($L$25+AH5) -> 41882.38 | S26: =SUM($L$25+AI5) -> 43582.4
A27: 211-115-001 | B27: Powered Boom, XL Top Arm 1400mm, SH 200mm | D27: ='2025_03_28 Boom Pricing'!$E$5+'2025_03_28 Boom Pricing'!$E$23+'2025_03_28 Boom Pricing'!$E$42+'2025_03_28 Boom Pricing'!$E$46 -> 38503.627 | E27: =D27*(1-0.5) -> 19251.813 | M27: 600 | N27: =SUM($L$25+AD6) -> 42270.27 | O27: =SUM($L$25+AE6) -> 42270.27 | P27: =SUM($L$25+AF6) -> 42270.27 | Q27: =SUM($L$25+AG6) -> 42270.27 | R27: =SUM($L$25+AH6) -> 43861.82 | S27: =SUM($L$25+AI6) -> 45562.24
A28: 211-116-001 | B28: Powered Boom, XL Top Arm 1600mm, SH 200mm | D28: ='2025_03_28 Boom Pricing'!$E$5+'2025_03_28 Boom Pricing'!$E$23+'2025_03_28 Boom Pricing'!$E$43+'2025_03_28 Boom Pricing'!$E$46 -> 40204.053 | E28: =D28*(1-0.5) -> 20102.027 | M28: 800 | N28: =SUM($L$25+AD7) -> 44309.39 | O28: =SUM($L$25+AE7) -> 44309.39 | P28: =SUM($L$25+AF7) -> 44309.39 | Q28: =SUM($L$25+AG7) -> 44309.39 | R28: =SUM($L$25+AH7) -> 45900.94 | S28: =SUM($L$25+AI7) -> 47601.36
A29: 211-111-002 | B29: Powered Boom, XL Top Arm 600mm, SH 400mm | D29: ='2025_03_28 Boom Pricing'!$E$5+'2025_03_28 Boom Pricing'!$E$24+'2025_03_28 Boom Pricing'!$E$38+'2025_03_28 Boom Pricing'!$E$46 -> 38886.987 | E29: =D29*(1-0.5) -> 19443.493 | M29: 1000 | N29: =SUM($L$25+AD8) -> 46343.55 | O29: =SUM($L$25+AE8) -> 46343.55 | P29: =SUM($L$25+AF8) -> 46343.55 | Q29: =SUM($L$25+AG8) -> 46343.55 | R29: =SUM($L$25+AH8) -> 47935.1 | S29: =SUM($L$25+AI8) -> 49635.52
A30: 211-112-002 | B30: Powered Boom, XL Top Arm 800mm, SH 400mm | D30: ='2025_03_28 Boom Pricing'!$E$5+'2025_03_28 Boom Pricing'!$E$24+'2025_03_28 Boom Pricing'!$E$39+'2025_03_28 Boom Pricing'!$E$46 -> 38886.987 | E30: =D30*(1-0.5) -> 19443.493
A31: 211-113-002 | B31: Powered Boom, XL Top Arm 1000mm, SH 400mm | D31: ='2025_03_28 Boom Pricing'!$E$5+'2025_03_28 Boom Pricing'!$E$24+'2025_03_28 Boom Pricing'!$E$40+'2025_03_28 Boom Pricing'!$E$46 -> 38886.987 | E31: =D31*(1-0.5) -> 19443.493 | K31: Standard Top Arm | L31: Fixed | N31: 600 | O31: 800 | P31: 1000 | Q31: 1200 | R31: 1400 | S31: 1600 | U31: Incorporate "sales price" and discounted List price
A32: 211-114-002 | B32: Powered Boom, XL Top Arm 1200mm, SH 400mm | D32: ='2025_03_28 Boom Pricing'!$E$5+'2025_03_28 Boom Pricing'!$E$24+'2025_03_28 Boom Pricing'!$E$41+'2025_03_28 Boom Pricing'!$E$46 -> 38886.987 | E32: =D32*(1-0.5) -> 19443.493 | K32: Standard Fixeed Arm (1000mm) | L32: 23781.02 | M32: 200 | N32: =SUM($L$32+AD4) -> 23781.02 | O32: =SUM($L$32+AE4) -> 23781.02 | P32: =SUM($L$32+AF4) -> 23781.02 | Q32: =SUM($L$32+AG4) -> 23781.02 | R32: na | S32: na
A33: 211-115-002 | B33: Powered Boom, XL Top Arm 1400mm, SH 400mm | D33: ='2025_03_28 Boom Pricing'!$E$5+'2025_03_28 Boom Pricing'!$E$24+'2025_03_28 Boom Pricing'!$E$42+'2025_03_28 Boom Pricing'!$E$46 -> 40478.533 | E33: =D33*(1-0.5) -> 20239.267 | M33: 400 | N33: =SUM($L$32+AD5) -> 25755.93 | O33: =SUM($L$32+AE5) -> 25755.93 | P33: =SUM($L$32+AF5) -> 25755.93 | Q33: =SUM($L$32+AG5) -> 25755.93 | R33: na | S33: na
A34: 211-116-002 | B34: Powered Boom, XL Top Arm 1600mm, SH 400mm | D34: ='2025_03_28 Boom Pricing'!$E$5+'2025_03_28 Boom Pricing'!$E$24+'2025_03_28 Boom Pricing'!$E$43+'2025_03_28 Boom Pricing'!$E$46 -> 42178.96 | E34: =D34*(1-0.5) -> 21089.48 | M34: 600 | N34: =SUM($L$32+AD6) -> 27735.77 | O34: =SUM($L$32+AE6) -> 27735.77 | P34: =SUM($L$32+AF6) -> 27735.77 | Q34: =SUM($L$32+AG6) -> 27735.77 | R34: na | S34: na
A35: 211-111-003 | B35: Powered Boom, XL Top Arm 600mm, SH 600mm | D35: ='2025_03_28 Boom Pricing'!$E$5+'2025_03_28 Boom Pricing'!$E$25+'2025_03_28 Boom Pricing'!$E$38+'2025_03_28 Boom Pricing'!$E$46 -> 40866.827 | E35: =D35*(1-0.5) -> 20433.413 | M35: 800 | N35: =SUM($L$32+AD7) -> 29774.89 | O35: =SUM($L$32+AE7) -> 29774.89 | P35: =SUM($L$32+AF7) -> 29774.89 | Q35: =SUM($L$32+AG7) -> 29774.89 | R35: na | S35: na
A36: 211-112-003 | B36: Powered Boom, XL Top Arm 800mm, SH 600mm | D36: ='2025_03_28 Boom Pricing'!$E$5+'2025_03_28 Boom Pricing'!$E$25+'2025_03_28 Boom Pricing'!$E$39+'2025_03_28 Boom Pricing'!$E$46 -> 40866.827 | E36: =D36*(1-0.5) -> 20433.413 | M36: 1000 | N36: =SUM($L$32+AD8) -> 31809.05 | O36: =SUM($L$32+AE8) -> 31809.05 | P36: =SUM($L$32+AF8) -> 31809.05 | Q36: =SUM($L$32+AG8) -> 31809.05 | R36: na | S36: na
A37: 211-113-003 | B37: Powered Boom, XL Top Arm 1000mm, SH 600mm | D37: ='2025_03_28 Boom Pricing'!$E$5+'2025_03_28 Boom Pricing'!$E$25+'2025_03_28 Boom Pricing'!$E$40+'2025_03_28 Boom Pricing'!$E$46 -> 40866.827 | E37: =D37*(1-0.5) -> 20433.413
A38: 211-114-003 | B38: Powered Boom, XL Top Arm 1200mm, SH 600mm | D38: ='2025_03_28 Boom Pricing'!$E$5+'2025_03_28 Boom Pricing'!$E$25+'2025_03_28 Boom Pricing'!$E$41+'2025_03_28 Boom Pricing'!$E$46 -> 40866.827 | E38: =D38*(1-0.5) -> 20433.413 | K38: XL Top Arm | L38: Fixed XL | N38: 600 | O38: 800 | P38: 1000 | Q38: 1200 | R38: 1400 | S38: 1600
A39: 211-115-003 | B39: Powered Boom, XL Top Arm 1400mm, SH 600mm | D39: ='2025_03_28 Boom Pricing'!$E$5+'2025_03_28 Boom Pricing'!$E$25+'2025_03_28 Boom Pricing'!$E$42+'2025_03_28 Boom Pricing'!$E$46 -> 42458.373 | E39: =D39*(1-0.5) -> 21229.187 | K39: Standard Fixeed Arm (1000mm) | L39: 27382.03 | M39: 200 | N39: =SUM($L$39+AD4) -> 27382.03 | O39: =SUM($L$39+AE4) -> 27382.03 | P39: =SUM($L$39+AF4) -> 27382.03 | Q39: =SUM($L$39+AG4) -> 27382.03 | R39: =SUM($L$39+AH4) -> 28973.58 | S39: =SUM($L$39+AI4) -> 30674
A40: 211-116-003 | B40: Powered Boom, XL Top Arm 1600mm, SH 600mm | D40: ='2025_03_28 Boom Pricing'!$E$5+'2025_03_28 Boom Pricing'!$E$25+'2025_03_28 Boom Pricing'!$E$43+'2025_03_28 Boom Pricing'!$E$46 -> 44158.8 | E40: =D40*(1-0.5) -> 22079.4 | M40: 400 | N40: =SUM($L$39+AD5) -> 29356.94 | O40: =SUM($L$39+AE5) -> 29356.94 | P40: =SUM($L$39+AF5) -> 29356.94 | Q40: =SUM($L$39+AG5) -> 29356.94 | R40: =SUM($L$39+AH5) -> 30948.89 | S40: =SUM($L$39+AI5) -> 32648.91
...

Sheet 2025_03_28 Boom Pricing
A1: Base Model
B2: Base Model | C2: Ondal List Price | D2: Imagine Cost | E2: Imagine List Price | G2: XL Arm? | H2: Articulating? | I2: Ondal Discount
B4: Boom - Powered Bottom Arm | C4: ='[1]Ondal Configs'!C2 -> 12369.17 | D4: =C4*(1-$I$4) -> 9895.336 | E4: =D4/(1-0.4)*2 -> 32984.453 | F4: 1000mm | G4: No | H4: Yes | I4: 0.2
B5: Boom - Arm (Powered XL) | C5: ='[1]Ondal Configs'!D2 -> 13842.03 | D5: =C5*(1-$I$4) -> 11073.624 | E5: =D5/(1-0.4)*2 -> 36912.08 | F5: 1000mm | G5: Yes | H5: Yes
B6: Boom - Spring Bottom Arm | C6: ='[1]Ondal Configs'!E2 -> 11692.64 | D6: =C6*(1-$I$4) -> 9354.112 | E6: =D6/(1-0.4)*2 -> 31180.373 | F6: 1000mm | G6: No | H6: Yes
B7: Boom - Spring Bottom Arm (XL) | C7: ='[1]Ondal Configs'!F2 -> 13462.94 | D7: =C7*(1-$I$4) -> 10770.352 | E7: =D7/(1-0.4)*2 -> 35901.173 | F7: 1000mm | G7: Yes | H7: Yes
B8: Boom - Fixed Bottom Arm | C8: ='[1]Ondal Configs'!G2 -> 8012.5 | D8: =C8*(1-$I$4) -> 6410 | E8: =D8/(1-0.4)*2 -> 21366.667 | F8: 1000mm | G8: No | H8: No
B9: Boom - Fixed Bottom Arm (XL) | C9: ='[1]Ondal Configs'!H2 -> 9362.88 | D9: =C9*(1-$I$4) -> 7490.304 | E9: =D9/(1-0.4)*2 -> 24967.68 | F9: 1000mm | G9: Yes | H9: No
B10: Fixed XXL | C10: ='[1]Ondal Configs'!I2 -> 10737.34 | D10: =C10*(1-$I$4) -> 8589.872 | E10: =D10/(1-0.4)*2 -> 28632.907 | G10: Yes | H10: No
B11: Large Monitor Boom | C11: 17141.96 | D11: =C11*(1-$I$4) -> 13713.568 | E11: =D11/(1-0.4)*2 -> 45711.893 | G11: Yes | H11: Yes
B12: Large Monitor Boom XL | C12: 19004 | D12: =C12*(1-$I$4) -> 15203.2 | E12: =D12/(1-0.4)*2 -> 50677.333 | G12: Yes | H12: Yes
B13: ="'Future' Boom" -> 'Future' Boom | C13: 0 | D13: =C13*(1-$I$4) -> 0 | E13: =D13/(1-0.4)*2 -> 0 | G13: No | H13: No
A15: Ondal Options | B15: Ceiling Cover | C15: Ondal List Price | D15: Imagine Cost | E15: Imagine List Price
I16: Placeholder
A17: 11-300-603 | B17: Boom - Single Square Ceiling Cover | C17: =SUM(C166:C168) -> 1536.74 | D17: =C17*(1-$I$4) -> 1229.392 | E17: =D17/(1-0.4)*2 -> 4097.9733 | I17: Future Boom | J17: 0
A18: 11-300-611 | B18: Tandem (1st Position) | C18: =SUM(C166:C168) -> 1536.74 | D18: =C18*(1-$I$4) -> 1229.392 | E18: =D18/(1-0.4)*2 -> 4097.9733
A19: 11-300-612 | B19: Tandem (2nd Position) | C19: 0 | D19: =C19*(1-$I$4) -> 0 | E19: =D19/(1-0.4)*2 -> 0
B21: Service Head
B23: Boom - Service Head | C23: 0 | D23: =C23*(1-$I$4) -> 0 | E23: =D23/(1-0.4)*2 -> 0 | F23: 200mm
B24: Boom - Service Head | C24: =C100+$C$130*2 -> 740.59 | D24: =C24*(1-$I$4) -> 592.472 | E24: =D24/(1-0.4)*2 -> 1974.9067 | F24: 400mm
B25: Boom - Service Head | C25: =C101+$C$130*4 -> 1483.03 | D25: =C25*(1-$I$4) -> 1186.424 | E25: =D25/(1-0.4)*2 -> 3954.7467 | F25: 600mm
B26: Boom - Service Head | C26: =C102+$C$130*6 -> 2247.7 | D26: =C26*(1-$I$4) -> 1798.16 | E26: =D26/(1-0.4)*2 -> 5993.8667 | F26: 800mm
B27: Boom - Service Head | C27: =C103+$C$130*8 -> 3010.51 | D27: =C27*(1-$I$4) -> 2408.408 | E27: =D27/(1-0.4)*2 -> 8028.0267 | F27: 1000mm
B28: Ceiling Tube
B30: Boom - Ceiling Flange | C30: 0 | D30: =C30*(1-$I$4) -> 0 | E30: =D30/(1-0.4)*2 -> 0 | F30: 100mm
B31: Boom - Ceiling Flange | C31: =C106 -> 94.43 | D31: =C31*(1-$I$4) -> 75.544 | E31: =D31/(1-0.4)*2 -> 251.81333 | F31: 300mm
B32: Boom - Ceiling Flange | C32: =C107 -> 185.15 | D32: =C32*(1-$I$4) -> 148.12 | E32: =D32/(1-0.4)*2 -> 493.73333 | F32: 500mm
B33: Boom - Ceiling Flange (XL) | C33: =C104 -> 0 | D33: =C33*(1-$I$4) -> 0 | E33: =D33/(1-0.4)*2 -> 0 | F33: 100mm
B34: Boom - Ceiling Flange (XL) | C34: =C110 -> 190.7 | D34: =C34*(1-$I$4) -> 152.56 | E34: =D34/(1-0.4)*2 -> 508.53333 | F34: 300mm
B35: Boom - Ceiling Flange (XL) | C35: =C111 -> 455.47 | D35: =C35*(1-$I$4) -> 364.376 | E35: =D35/(1-0.4)*2 -> 1214.5867 | F35: 500mm
B36: Top Arm
B38: Boom - Fixed Top Arm | C38: 0 | D38: =C38*(1-$I$4) -> 0 | E38: =D38/(1-0.4)*2 -> 0 | F38: 600mm
B39: Boom - Fixed Top Arm | C39: 0 | D39: =C39*(1-$I$4) -> 0 | E39: =D39/(1-0.4)*2 -> 0 | F39: 800mm
B40: Boom - Fixed Top Arm | C40: 0 | D40: =C40*(1-$I$4) -> 0 | E40: =D40/(1-0.4)*2 -> 0 | F40: 1000mm
B41: Boom - Fixed Top Arm | C41: 0 | D41: =C41*(1-$I$4) -> 0 | E41: =D41/(1-0.4)*2 -> 0 | F41: 1200mm
B42: Boom - Fixed Top Arm | C42: =C122 -> 596.83 | D42: =C42*(1-$I$4) -> 477.464 | E42: =D42/(1-0.4)*2 -> 1591.5467 | F42: 1400mm
B43: Boom - Fixed Top Arm | C43: =C123 -> 1234.49 | D43: =C43*(1-$I$4) -> 987.592 | E43: =D43/(1-0.4)*2 -> 3291.9733 | F43: 1600mm
B44: Bottom Arm
B46: Articulating Bottom Arm | C46: 0 | D46: =C46*(1-$I$4) -> 0 | E46: =D46/(1-0.4)*2 -> 0
B47: Bottom Arm | C47: 1 | D47: =C47*(1-$I$4) -> 0.8 | E47: =D47/(1-0.4)*2 -> 2.6666667 | F47: 600mm
...

Sheet 2025_03_28 3D Light Pricing
A1: Part Number | B1: Configuration | C1: Current 3D Tool Config (Top to bottom) | D1: Imagine List Price | E1: Imagine Sales Price | G1: Sections | H1: Part Number
A2: 111-001111 | B2: 7000 - LED | C2: Lights - U | ONE | D2: ='2025_03_28 Light Pricing'!$H$4+'2025_03_28 Light Pricing'!H23 -> 37407.7 | E2: =D2*$H$11 -> 18703.85 | G2: 7000/ U|ONE Lights and all variations | H2: 111
A3: 111-001112 | B3: 7000 - LED / LED | C3: Lights - U | ONE Lights - U | ONE | D3: ='2025_03_28 Light Pricing'!$H$5+'2025_03_28 Light Pricing'!H23+'2025_03_28 Light Pricing'!H23 -> 73942.55 | E3: =D3*$H$11 -> 36971.275 | G3: No light configs (not including booms) | H3: 112
A4: 111-001113 | B4: 7000 - LED / LED / LED | C4: Lights -U|ONE,Lights - U|ONE,Lights - U|ONE | D4: ='2025_03_28 Light Pricing'!$H$6+'2025_03_28 Light Pricing'!H23+'2025_03_28 Light Pricing'!H23+'2025_03_28 Light Pricing'!H23 -> 106014.52 | E4: =D4*$H$11 -> 53007.258 | G4: 8000/ U|002 Lights and all variations | H4: 113
A5: 111-001114 | B5: 7000 - LED / FP | C5: Lights -U|ONE, Lights - Flat Panel Carrier | D5: ='2025_03_28 Light Pricing'!$H$7+'2025_03_28 Light Pricing'!H23+'2025_03_28 Light Pricing'!$H$27 -> 54751.183 | E5: =D5*$H$11 -> 27375.592 | G5: Sim.Flex | H5: 114
A6: 111-001115 | B6: 7000 - FP / LED | C6: Lights - Flat Panel Carrier, Lights -U|ONE | D6: ='2025_03_28 Light Pricing'!$H$8+'2025_03_28 Light Pricing'!$H$27+'2025_03_28 Light Pricing'!H23 -> 54376.533 | E6: =D6*$H$11 -> 27188.267 | G6: Drop Down Options | H6: 115
A7: 111-001116 | B7: 7000 - LED / LED / FP | C7: Lights -U|ONE,Lights - U|ONE,Lights - Flat Panel Carrier | D7: ='2025_03_28 Light Pricing'!$H$9+'2025_03_28 Light Pricing'!H23+'2025_03_28 Light Pricing'!H23+'2025_03_28 Light Pricing'!$H$27 -> 89254.35 | E7: =D7*$H$11 -> 44627.175 | G7: Light Exchange | H7: 116
A8: 111-001117 | B8: 7000 - LED / LS | C8: Lights -U|ONE, Lights - Flat Panel Carrier | D8: ='2025_03_28 Light Pricing'!$H$10+'2025_03_28 Light Pricing'!H23+'2025_03_28 Light Pricing'!$H$28 -> 63174.183 | E8: =D8*$H$11 -> 31587.092 | G8: Shipping & Installation | H8: 117
A9: 111-001118 | B9: 7000 - LED / LED / LS | C9: Lights -U|ONE, Lights - U|ONE, Lights - Flat Panel Carrier | D9: ='2025_03_28 Light Pricing'!$H$11+'2025_03_28 Light Pricing'!H23+'2025_03_28 Light Pricing'!H23+'2025_03_28 Light Pricing'!$H$28 -> 95246.15 | E9: =D9*$H$11 -> 47623.075
A10: 111-001119 | B10: 7000 LC - LED | C10: Lights - U|ONE (Low Ceiling) | D10: ='2025_03_28 Light Pricing'!$H$4+'2025_03_28 Light Pricing'!H25 -> 39936.433 | E10: =D10*$H$11 -> 19968.217 | H10: Light Discount
A11: 111-001120 | B11: 7000 LC - LED / LED | C11: Lights - U|ONE (Low Ceiling),Lights - U|ONE (Low Ceiling) | D11: ='2025_03_28 Light Pricing'!$H$5+'2025_03_28 Light Pricing'!H25+'2025_03_28 Light Pricing'!H25 -> 79000.017 | E11: =D11*$H$11 -> 39500.008 | H11: 0.5
A12: 111-001121 | B12: 7000 LC - LED / LED / LED | C12: Lights - U|ONE (Low Ceiling),Lights - U|ONE (Low Ceiling),Lights - U|ONE (Low Ceiling) | D12: ='2025_03_28 Light Pricing'!$H$6+'2025_03_28 Light Pricing'!H25+'2025_03_28 Light Pricing'!H25+'2025_03_28 Light Pricing'!H25 -> 113600.72 | E12: =D12*$H$11 -> 56800.358
A13: 111-001122 | B13: 7000 LC - LED / FP | C13: Lights - U|ONE (Low Ceiling), Lights - Flat Panel Carrier | D13: ='2025_03_28 Light Pricing'!$H$7+'2025_03_28 Light Pricing'!H25+'2025_03_28 Light Pricing'!$H$27 -> 57279.917 | E13: =D13*$H$11 -> 28639.958
A14: 111-001123 | B14: 7000 LC - FP / LED | C14: Lights - Flat Panel Carrier, Lights - U|ONE (Low Ceiling) | D14: ='2025_03_28 Light Pricing'!$H$8+'2025_03_28 Light Pricing'!$H$27+'2025_03_28 Light Pricing'!H25 -> 56905.267 | E14: =D14*$H$11 -> 28452.633
A15: 111-001124 | B15: 7000 LC - LED / LED / FP | C15: Lights - U|ONE (Low Ceiling),Lights - U|ONE (Low Ceiling), Lights - Flat Panel Carrier | D15: ='2025_03_28 Light Pricing'!$H$9+'2025_03_28 Light Pricing'!H25+'2025_03_28 Light Pricing'!H25+'2025_03_28 Light Pricing'!$H$27 -> 94311.817 | E15: =D15*$H$11 -> 47155.908
A16: 111-001125 | B16: 7000 LC - LED / LS | C16: Lights - U|ONE (Low Ceiling), Lights - Flat Panel Carrier | D16: ='2025_03_28 Light Pricing'!$H$10+'2025_03_28 Light Pricing'!H25+'2025_03_28 Light Pricing'!$H$28 -> 65702.917 | E16: =D16*$H$11 -> 32851.458
A17: 111-001126 | B17: 7000 LC - LED / LED / LS | C17: Lights - U|ONE (Low Ceiling),Lights - U|ONE (Low Ceiling), Lights - Flat Panel Carrier | D17: ='2025_03_28 Light Pricing'!$H$11+'2025_03_28 Light Pricing'!H25+'2025_03_28 Light Pricing'!H25+'2025_03_28 Light Pricing'!$H$28 -> 100303.62 | E17: =D17*$H$11 -> 50151.808
A18: 112-001111 | B18: No Lights - FP | C18: Lights - Flat Panel Carrier | D18: ='2025_03_28 Light Pricing'!H12+'2025_03_28 Light Pricing'!H27 -> 20611 | E18: =D18*$H$11 -> 10305.5
A19: 112-001112 | B19: No Lights - LS | C19: Lights - Lead Shield | D19: ='2025_03_28 Light Pricing'!H13+'2025_03_28 Light Pricing'!H28 -> 26639.333 | E19: =D19*$H$11 -> 13319.667
A20: 112-001113 | B20: No Lights - FP / FP | C20: Lights - Flat Panel Carrier, Lights - Flat Panel Carrier | D20: ='2025_03_28 Light Pricing'!H14+'2025_03_28 Light Pricing'!H27+'2025_03_28 Light Pricing'!H27 -> 38481.933 | E20: =D20*$H$11 -> 19240.967
A21: 112-001114 | B21: No Lights - LS / LS | C21: Lights - Lead Shield, Lights - Lead Shield | D21: ='2025_03_28 Light Pricing'!H15+'2025_03_28 Light Pricing'!H28+'2025_03_28 Light Pricing'!H28 -> 52405.817 | E21: =D21*$H$11 -> 26202.908
A22: 112-001115 | B22: No Lights - FP / LS | C22: Lights - Flat Panel Carrier, Lights - Lead Shield | D22: ='2025_03_28 Light Pricing'!H16+'2025_03_28 Light Pricing'!H27+'2025_03_28 Light Pricing'!H28 -> 43608.167 | E22: =D22*$H$11 -> 21804.083
A23: 112-001116 | B23: No Lights - LS / FP | C23: Lights - Lead Shield, Lights - Flat Panel Carrier | D23: ='2025_03_28 Light Pricing'!H17+'2025_03_28 Light Pricing'!H28+'2025_03_28 Light Pricing'!H27 -> 43982.817 | E23: =D23*$H$11 -> 21991.408
A24: 112-001117 | B24: No Lights - TC FP (Ondal) | C24: TC Flat Panel (no model currently in the tool) | D24: ='2025_03_28 Light Pricing'!H33 -> 22500 | E24: =D24*$H$11 -> 11250
A25: 113-001111 | B25: 8000 - LED | C25: Lights - U|002 Standard | D25: ='2025_03_28 Light Pricing'!$H$4+'2025_03_28 Light Pricing'!$H$26 -> 41940.133 | E25: =D25*$H$11 -> 20970.067
A26: 113-001112 | B26: 8000 - LED / LED | C26: Lights - U|002,Lights - U|002 | D26: ='2025_03_28 Light Pricing'!$H$5+'2025_03_28 Light Pricing'!$H$26+'2025_03_28 Light Pricing'!$H$26 -> 83007.417 | E26: =D26*$H$11 -> 41503.708
A27: 113-001113 | B27: 8000 - LED / LED / LED | C27: Lights - U|002,Lights - U|002, Lights - U|002 | D27: ='2025_03_28 Light Pricing'!$H$6+'2025_03_28 Light Pricing'!$H$26+'2025_03_28 Light Pricing'!$H$26+'2025_03_28 Light Pricing'!$H$26 -> 119611.82 | E27: =D27*$H$11 -> 59805.908
A28: 113-001114 | B28: 8000 - LED / FP | C28: Lights - U|002, Lights - Flat Panel Carrier | D28: ='2025_03_28 Light Pricing'!$H$7+'2025_03_28 Light Pricing'!$H$26+'2025_03_28 Light Pricing'!$H$27 -> 59283.617 | E28: =D28*$H$11 -> 29641.808
A29: 113-001115 | B29: 8000 - FP / LED | C29: Lights - Flat Panel Carrier,Lights - U|002 | D29: ='2025_03_28 Light Pricing'!$H$8+'2025_03_28 Light Pricing'!$H$27+'2025_03_28 Light Pricing'!$H$26 -> 58908.967 | E29: =D29*$H$11 -> 29454.483
A30: 113-001116 | B30: 8000 - LED / LED / FP | C30: Lights - U|002,Lights - U|002, Lights - Flat Panel Carrier | D30: ='2025_03_28 Light Pricing'!$H$9+'2025_03_28 Light Pricing'!$H$26+'2025_03_28 Light Pricing'!$H$26+'2025_03_28 Light Pricing'!$H$27 -> 98319.217 | E30: =D30*$H$11 -> 49159.608
A31: 113-001117 | B31: 8000 - LED / LS | C31: Lights - U|002, Lights - Flat Panel Carrier | D31: ='2025_03_28 Light Pricing'!$H$10+'2025_03_28 Light Pricing'!$H$26+'2025_03_28 Light Pricing'!$H$28 -> 67706.617 | E31: =D31*$H$11 -> 33853.308
A32: 113-001118 | B32: 8000 - LED / LED / LS | C32: Lights - U|002, Lights - U|002, Lights - Lead Shield | D32: ='2025_03_28 Light Pricing'!$H$11+'2025_03_28 Light Pricing'!$H$26+'2025_03_28 Light Pricing'!$H$26+'2025_03_28 Light Pricing'!$H$28 -> 104311.02 | E32: =D32*$H$11 -> 52155.508
A33: 113-001119 | B33: 8000 LC - LED | C33: Lights - U | 002 (Low Ceiling) | D33: ='2025_03_28 Light Pricing'!$H$4+'2025_03_28 Light Pricing'!$H$26 -> 41940.133 | E33: =D33*$H$11 -> 20970.067
A34: 113-001120 | B34: 8000 LC - LED / LED | C34: Lights - U|002 LC, Lights - U|002 LC | D34: ='2025_03_28 Light Pricing'!$H$5+'2025_03_28 Light Pricing'!$H$26+'2025_03_28 Light Pricing'!$H$26 -> 83007.417 | E34: =D34*$H$11 -> 41503.708
A35: 113-001121 | B35: 8000 LC - LED / LED / LED | C35: Lights - U|002LC ,Lights - U|002 LC,Lights - U|002 LC | D35: ='2025_03_28 Light Pricing'!$H$6+'2025_03_28 Light Pricing'!$H$26+'2025_03_28 Light Pricing'!$H$26+'2025_03_28 Light Pricing'!$H$26 -> 119611.82 | E35: =D35*$H$11 -> 59805.908
A36: 113-001122 | B36: 8000 LC - LED / FP | C36: Lights - U|002 LC, Lights - Flat Panel Carrier | D36: ='2025_03_28 Light Pricing'!$H$7+'2025_03_28 Light Pricing'!$H$26+'2025_03_28 Light Pricing'!$H$27 -> 59283.617 | E36: =D36*$H$11 -> 29641.808
A37: 113-001123 | B37: 8000 LC - FP / LED | C37: Lights - Flat Panel Carrier, U|002 LC | D37: ='2025_03_28 Light Pricing'!$H$8+'2025_03_28 Light Pricing'!$H$27+'2025_03_28 Light Pricing'!$H$26 -> 58908.967 | E37: =D37*$H$11 -> 29454.483
A38: 113-001124 | B38: 8000 LC - LED / LED / FP | C38: Lights - U|002 LC, Lights - U|002 LC, Lights - Flat Panel Carrier | D38: ='2025_03_28 Light Pricing'!$H$9+'2025_03_28 Light Pricing'!$H$26+'2025_03_28 Light Pricing'!$H$26+'2025_03_28 Light Pricing'!$H$27 -> 98319.217 | E38: =D38*$H$11 -> 49159.608
A39: 113-001125 | B39: 8000 LC - LED / LS | C39: Lights - U|002 LC, Lights - Flat Panel Carrier | D39: ='2025_03_28 Light Pricing'!$H$10+'2025_03_28 Light Pricing'!$H$26+'2025_03_28 Light Pricing'!$H$28 -> 67706.617 | E39: =D39*$H$11 -> 33853.308
A40: 113-001126 | B40: 8000 LC - LED / LED / LS | C40: Lights - U|002LC ,Lights - U|002LC , Lights - Lead Shield | D40: ='2025_03_28 Light Pricing'!$H$11+'2025_03_28 Light Pricing'!$H$26+'2025_03_28 Light Pricing'!$H$26+'2025_03_28 Light Pricing'!$H$28 -> 104311.02 | E40: =D40*$H$11 -> 52155.508
...

Sheet 2025_03_28 Light Pricing
A1: Base Model(s) | D1: 0
B2: Part # | C2: Base Model | D2: # of Arms | E2: # of Lights | F2: TC Mount? | G2: Imagine Cost | H2: Imagine List Price | J2: Ceiling Tube | K2: Central Axis | L2: Turning Cover
B4: 11-100-101 | C4: LED | D4: 1 | E4: 1 | F4: No | G4: =SUM(J4:L4) -> 2075.235 | H4: =G4/(1-0.4)*2 -> 6917.45 | J4: =F195 -> 381.6 | K4: =F108 -> 1693.635 | L4: 0
B5: 11-100-102 | C5: LED / LED | D5: 2 | E5: 2 | F5: No | G5: =SUM(J5:L5) -> 3888.615 | H5: =G5/(1-0.4)*2 -> 12962.05 | J5: =F196 -> 381.6 | K5: =F117 -> 3507.015 | L5: 0
B6: 11-100-103 | C6: LED / LED / LED | D6: 3 | E6: 3 | F6: No | G6: =SUM(J6:L6) -> 4363.13 | H6: =G6/(1-0.4)*2 -> 14543.767 | J6: =F197 -> 381.6 | K6: =F124 -> 3981.53 | L6: 0
B7: 11-100-104 | C7: LED / FP | D7: 2 | E7: 1 | F7: No | G7: =SUM(J7:L7) -> 2889.055 | H7: =G7/(1-0.4)*2 -> 9630.1833 | J7: =F198 -> 381.6 | K7: =F115 -> 2311.44 | L7: =F158 -> 196.015
B8: 11-100-105 | C8: FP / LED | D8: 2 | E8: 1 | F8: No | G8: =SUM(J8:L8) -> 2776.66 | H8: =G8/(1-0.4)*2 -> 9255.5333 | J8: =F199 -> 381.6 | K8: =F116 -> 2395.06 | L8: 0
B9: 11-100-106 | C9: LED / LED / FP | D9: 3 | E9: 2 | F9: No | G9: =SUM(J9:L9) -> 4092.93 | H9: =G9/(1-0.4)*2 -> 13643.1 | J9: =F200 -> 381.6 | K9: =F123 -> 3515.315 | L9: =F158 -> 196.015
B10: 11-100-107 | C10: LED / LS | D10: 2 | E10: 1 | F10: No | G10: =SUM(J10:L10) -> 3888.615 | H10: =G10/(1-0.4)*2 -> 12962.05 | J10: =F201 -> 381.6 | K10: =F117 -> 3507.015 | L10: 0
B11: 11-100-108 | C11: LED / LED / LS | D11: 3 | E11: 2 | F11: No | G11: =SUM(J11:L11) -> 4363.13 | H11: =G11/(1-0.4)*2 -> 14543.767 | J11: =F202 -> 381.6 | K11: =F124 -> 3981.53 | L11: 0
B12: 11-100-109 | C12: FP | D12: 1 | E12: 0 | F12: No | G12: =SUM(J12:L12) -> 1794.075 | H12: =G12/(1-0.4)*2 -> 5980.25 | J12: =F203 -> 381.6 | K12: =F109 -> 1412.475 | L12: 0
B13: 11-100-110 | C13: LS | D13: 1 | E13: 0 | F13: No | G13: =SUM(J13:L13) -> 2075.235 | H13: =G13/(1-0.4)*2 -> 6917.45 | J13: =F204 -> 381.6 | K13: =F108 -> 1693.635 | L13: 0
B14: 11-100-111 | C14: FP / FP | D14: 2 | E14: 0 | F14: No | G14: =SUM(J14:L14) -> 2766.13 | H14: =G14/(1-0.4)*2 -> 9220.4333 | J14: =F205 -> 381.6 | K14: =F118 -> 2188.515 | L14: =F158 -> 196.015
B15: 11-100-112 | C15: LS / LS | D15: 2 | E15: 0 | F15: No | G15: =SUM(J15:L15) -> 3888.615 | H15: =G15/(1-0.4)*2 -> 12962.05 | J15: =F206 -> 381.6 | K15: =F117 -> 3507.015 | L15: 0
B16: 11-100-113 | C16: FP / LS | D16: 2 | E16: 0 | F16: No | G16: =SUM(J16:L16) -> 2776.66 | H16: =G16/(1-0.4)*2 -> 9255.5333 | J16: =F207 -> 381.6 | K16: =F116 -> 2395.06 | L16: 0
B17: 11-100-114 | C17: LS / FP | D17: 2 | E17: 0 | F17: No | G17: =SUM(J17:L17) -> 2889.055 | H17: =G17/(1-0.4)*2 -> 9630.1833 | J17: =F208 -> 381.6 | K17: =F115 -> 2311.44 | L17: =F158 -> 196.015
B18: 11-100-115 | C18: LED (3P) | D18: 1 | E18: 1 | F18: No | G18: =SUM(J18:L18) -> 1427.065 | H18: =G18/(1-0.4)*2 -> 4756.8833 | J18: =F209 -> 381.6 | K18: =F110 -> 1045.465 | L18: 0
A20: Priced Option(s)
B21: Part # | C21: Arm Selections | G21: Imagine Cost | H21: Imagine List Price | J21: Spring Arm | K21: Lighthead | L21: Flat Panel | M21: Lead Shield | N21: Power Supply | O21: Power Cable | P21: Control Cable
B23: 11-200-101 | C23: ="7000 Standard" -> 7000 Standard | D23: LED | G23: =SUM(J23:P23) -> 9147.075 | H23: =G23/(1-0.4)*2 -> 30490.25 | J23: =F129 -> 1162.445 | K23: =F140 -> 7008.815 | L23: 0 | M23: 0 | N23: =$F$163 -> 807.76 | O23: =$F$164 -> 99.705 | P23: =$F$165 -> 68.35
B24: 11-200-103 | C24: ="8000 Standard" -> 8000 Standard | D24: LED | G24: =SUM(J24:P24) -> 9756.54 | H24: =G24/(1-0.4)*2 -> 32521.8 | J24: =F129 -> 1162.445 | K24: =F136 -> 7618.28 | L24: 0 | M24: 0 | N24: =$F$163 -> 807.76 | O24: =$F$164 -> 99.705 | P24: =$F$165 -> 68.35
B25: 11-200-102 | C25: 7000 Low Ceiling | D25: LED | G25: =SUM(J25:P25) -> 9905.695 | H25: =G25/(1-0.4)*2 -> 33018.983 | J25: =F130 -> 2017.16 | K25: =F141 -> 6912.72 | L25: 0 | M25: 0 | N25: =$F$163 -> 807.76 | O25: =$F$164 -> 99.705 | P25: =$F$165 -> 68.35
B26: 11-200-104 | C26: 8000 Low Ceiling | D26: LED | G26: =SUM(J26:P26) -> 10506.805 | H26: =G26/(1-0.4)*2 -> 35022.683 | J26: =F130 -> 2017.16 | K26: =F137 -> 7513.83 | L26: 0 | M26: 0 | N26: =$F$163 -> 807.76 | O26: =$F$164 -> 99.705 | P26: =$F$165 -> 68.35
B27: 11-200-105 | C27: 32" Flat Panel | D27: FP | G27: =SUM(J27:P27) -> 4389.225 | H27: =G27/(1-0.4)*2 -> 14630.75 | J27: =F131 -> 2007.095 | K27: =F183 -> 2382.13 | L27: 0 | M27: 0 | N27: 0 | O27: 0 | P27: 0
B28: 11-200-106 | C28: Lead Shield | D28: LED | G28: =SUM(J28:P28) -> 5916.565 | H28: =G28/(1-0.4)*2 -> 19721.883 | J28: =F129 -> 1162.445 | K28: =F186 -> 4754.12 | L28: 0 | M28: 0 | N28: 0 | O28: 0 | P28: 0
B29: 11-200-107 | C29: 500 Standard (3P) | D29: LED | G29: =SUM(J29:P29) -> 5788.945 | H29: =G29/(1-0.4)*2 -> 19296.483 | J29: =F127 -> 609.045 | K29: =F145 -> 4204.085 | L29: 0 | M29: 0 | N29: =$F$163 -> 807.76 | O29: =$F$164 -> 99.705 | P29: =$F$165 -> 68.35
B30: 11-200-107 | C30: 500 Low Ceiling (3P) | D30: LED | G30: =SUM(J30:P30) -> 6280.505 | H30: =G30/(1-0.4)*2 -> 20935.017 | J30: =F128 -> 1196.705 | K30: =F146 -> 4107.985 | L30: 0 | M30: 0 | N30: =$F$163 -> 807.76 | O30: =$F$164 -> 99.705 | P30: =$F$165 -> 68.35
B31: 11-200-108 | C31: 8000 Standard (3P) | D31: LED | G31: =SUM(J31:P31) -> 5788.945 | H31: =G31/(1-0.4)*2 -> 19296.483 | J31: =F127 -> 609.045 | K31: =F145 -> 4204.085 | L31: 0 | M31: 0 | N31: =$F$163 -> 807.76 | O31: =$F$164 -> 99.705 | P31: =$F$165 -> 68.35
B32: 11-200-108 | C32: 8000 Low Ceiling (3P) | D32: LED | G32: =SUM(J32:P32) -> 6280.505 | H32: =G32/(1-0.4)*2 -> 20935.017 | J32: =F128 -> 1196.705 | K32: =F146 -> 4107.985 | L32: 0 | M32: 0 | N32: =$F$163 -> 807.76 | O32: =$F$164 -> 99.705 | P32: =$F$165 -> 68.35
B33: 11-200-109 | C33: FP (TC-Ondal) | G33: =SUM(J33:P33) -> 6750 | H33: =G33/(1-0.4)*2 -> 22500 | J33: 0 | K33: =F189 -> 6750 | L33: 0 | M33: 0 | N33: 0 | O33: 0 | P33: 0
B34: 11-200-110 | C34: LED Upgrade | G34: =SUM(J34:P34) -> 7500 | H34: =G34/(1-0.4)*2 -> 25000 | J34: 0 | K34: 7500 | L34: 0 | M34: 0 | N34: 0 | O34: 0 | P34: 0
B35: 11-200-111 | C35: 4500 Exam Light | G35: =SUM(J35:P35) -> 3615.183 | H35: =G35/(1-0.4)*2 -> 12050.61 | J35: 0 | K35: =F149 -> 3615.183 | L35: 0 | M35: 0 | N35: 0 | O35: 0 | P35: 0
C37: Ceiling Drop Tubes | G37: Imagine Cost | H37: Imagine List Price
B39: 11-300-001 | C39: 150mm | G39: =SUM(J39:P39) -> 0 | H39: =G39/(1-0.4)*2 -> 0 | J39: 0 | K39: 0 | L39: 0 | M39: 0 | N39: 0 | O39: 0 | P39: 0
B40: 11-300-002 | C40: 200mm | G40: =SUM(J40:P40) -> 0 | H40: =G40/(1-0.4)*2 -> 0 | J40: 0 | K40: 0 | L40: 0 | M40: 0 | N40: 0 | O40: 0 | P40: 0
B41: 11-300-003 | C41: 250mm | G41: =SUM(J41:P41) -> 0 | H41: =G41/(1-0.4)*2 -> 0 | J41: 0 | K41: 0 | L41: 0 | M41: 0 | N41: 0 | O41: 0 | P41: 0
B42: 11-300-004 | C42: 300mm | G42: =SUM(J42:P42) -> 0 | H42: =G42/(1-0.4)*2 -> 0 | J42: 0 | K42: 0 | L42: 0 | M42: 0 | N42: 0 | O42: 0 | P42: 0
B43: 11-300-005 | C43: 350mm | G43: =SUM(J43:P43) -> 0 | H43: =G43/(1-0.4)*2 -> 0 | J43: 0 | K43: 0 | L43: 0 | M43: 0 | N43: 0 | O43: 0 | P43: 0
B44: 11-300-006 | C44: 400mm | G44: =SUM(J44:P44) -> 0 | H44: =G44/(1-0.4)*2 -> 0 | J44: 0 | K44: 0 | L44: 0 | M44: 0 | N44: 0 | O44: 0 | P44: 0
B45: 11-300-007 | C45: 450mm | G45: =SUM(J45:P45) -> 0 | H45: =G45/(1-0.4)*2 -> 0 | J45: 0 | K45: 0 | L45: 0 | M45: 0 | N45: 0 | O45: 0 | P45: 0
...

Sheet Light Pricing
A2: Base Model | D2: # of Arms | E2: # of Lights | F2: TC Mount?
A3: Part Number | B3: Description | C3: ="" | D3: 0 | E3: 0 | G3: Simeon List Price | H3: Imagine Cost | I3: Imagine List Price | J3: Imagine Sales Price | L3: Mounting Plate | M3: Ceiling Tube | N3: Ceiling Cover | O3: Central Axis | P3: Turning Cover | Q3: Arm 1 Pkg | R3: Arm 2 Pkg | S3: Arm 3 Pkg | T3: Arm 4 Pkg
B4: 500 LC - LED (3P) | C4: =B4 -> 500 LC - LED (3P) | D4: 1 | E4: 1 | F4: No | G4: =SUM(L4:AA4) -> 16357.74 | H4: =G4*(1-0.5) -> 8178.87 | I4: =H4/(1-0.4)*2 -> 27262.9 | J4: =I4*(1-0.5) -> 13631.45 | L4: =$D$128 -> 598.53 | M4: 763.02 | N4: 344.25 | O4: =D96 -> 2090.93 | P4: 0 | Q4: =M72 -> 12561.01
B5: LED | C5: 8000 - LED | D5: 1 | E5: 1 | F5: No | G5: =SUM(L5:AA5) -> 24397.25 | H5: =G5*0.5 -> 12198.625 | I5: =H5/(1-0.4)*2 -> 40662.083 | J5: =I5*(1-0.5) -> 20331.042 | L5: =$D$128 -> 598.53 | M5: 763.02 | N5: 344.25 | O5: =D97 -> 3387.27 | P5: 0 | Q5: =M75 -> 19304.18
B6: LED / LED | C6: 8000 - LED / LED | D6: 2 | E6: 2 | F6: No | G6: =SUM(L6:AA6) -> 47328.19 | H6: =G6*0.5 -> 23664.095 | I6: =H6/(1-0.4)*2 -> 78880.317 | J6: =I6*(1-0.5) -> 39440.158 | L6: =$D$128 -> 598.53 | M6: 763.02 | N6: 344.25 | O6: =D101 -> 7014.03 | P6: 0 | Q6: =M75 -> 19304.18 | R6: =M75 -> 19304.18
B7: LED / LED / LED | C7: 8000 - LED / LED / LED | D7: 3 | E7: 3 | F7: No | G7: =SUM(L7:AA7) -> 67581.4 | H7: =G7*0.5 -> 33790.7 | I7: =H7/(1-0.4)*2 -> 112635.67 | J7: =I7*(1-0.5) -> 56317.833 | L7: =$D$128 -> 598.53 | M7: 763.02 | N7: 344.25 | O7: =D107 -> 7963.06 | P7: 0 | Q7: =M75 -> 19304.18 | R7: =M75 -> 19304.18 | S7: =M75 -> 19304.18
B8: LED / FP | C8: 8000 - LED / FP | D8: 2 | E8: 1 | F8: No | G8: =SUM(L8:AA8) -> 34866.25 | H8: =G8*0.5 -> 17433.125 | I8: =H8/(1-0.4)*2 -> 58110.417 | J8: =I8*(1-0.5) -> 29055.208 | L8: =$D$128 -> 598.53 | M8: 763.02 | N8: 344.25 | O8: =D103 -> 4622.88 | P8: 392.03 | Q8: =M75 -> 19304.18 | R8: =M78 -> 8841.36
B9: FP / LED | C9: 8000 - FP / LED | D9: 2 | E9: 1 | F9: No | G9: =SUM(L9:AA9) -> 34641.46 | H9: =G9*0.5 -> 17320.73 | I9: =H9/(1-0.4)*2 -> 57735.767 | J9: =I9*(1-0.5) -> 28867.883 | L9: =$D$128 -> 598.53 | M9: 763.02 | N9: 344.25 | O9: =D102 -> 4790.12 | P9: 0 | Q9: =M78 -> 8841.36 | R9: =M75 -> 19304.18
B10: LED / LED / FP | C10: 8000 - LED / LED / FP | D10: 3 | E10: 2 | F10: No | G10: =SUM(L10:AA10) -> 56578.18 | H10: =G10*0.5 -> 28289.09 | I10: =H10/(1-0.4)*2 -> 94296.967 | J10: =I10*(1-0.5) -> 47148.483 | L10: =$D$128 -> 598.53 | M10: 763.02 | N10: 344.25 | O10: =D109 -> 7030.63 | P10: 392.03 | Q10: =M75 -> 19304.18 | R10: =M75 -> 19304.18 | S10: =M78 -> 8841.36
B11: LED / LS | C11: 8000 - LED / LS | D11: 2 | E11: 1 | F11: No | G11: =SUM(L11:AA11) -> 46673.28 | H11: =G11*0.5 -> 23336.64 | I11: =H11/(1-0.4)*2 -> 77788.8 | J11: =I11*(1-0.5) -> 38894.4 | L11: =$D$128 -> 598.53 | M11: 763.02 | N11: 344.25 | O11: =D101 -> 7014.03 | P11: 0 | Q11: =M75 -> 19304.18 | R11: =M80 -> 18649.27
B12: LED / LED / LS | C12: 8000 - LED / LED / LS | D12: 3 | E12: 2 | F12: No | G12: =SUM(L12:AA12) -> 66926.49 | H12: =G12*0.5 -> 33463.245 | I12: =H12/(1-0.4)*2 -> 111544.15 | J12: =I12*(1-0.5) -> 55772.075 | L12: =$D$128 -> 598.53 | M12: 763.02 | N12: 344.25 | O12: =D107 -> 7963.06 | P12: 0 | Q12: =M75 -> 19304.18 | R12: =M75 -> 19304.18 | S12: =M80 -> 18649.27
B13: FP | C13: ="No Lights - "&B13 -> No Lights - FP | D13: 1 | E13: 0 | F13: No | G13: =SUM(L13:AA13) -> 13372.11 | H13: =G13*0.5 -> 6686.055 | I13: =H13/(1-0.4)*2 -> 22286.85 | J13: =I13*(1-0.5) -> 11143.425 | L13: =$D$128 -> 598.53 | M13: 763.02 | N13: 344.25 | O13: =D98 -> 2824.95 | P13: 0 | Q13: =M78 -> 8841.36
B14: LS | C14: ="No Lights - "&B14 -> No Lights - LS | D14: 1 | E14: 0 | F14: No | G14: =SUM(L14:AA14) -> 23742.34 | H14: =G14*0.5 -> 11871.17 | I14: =H14/(1-0.4)*2 -> 39570.567 | J14: =I14*(1-0.5) -> 19785.283 | L14: =$D$128 -> 598.53 | M14: 763.02 | N14: 344.25 | O14: =D97 -> 3387.27 | P14: 0 | Q14: =M80 -> 18649.27
B15: FP / FP | C15: ="No Lights - "&B15 -> No Lights - FP / FP | D15: 2 | E15: 0 | F15: No | G15: =SUM(L15:AA15) -> 24157.58 | H15: =G15*0.5 -> 12078.79 | I15: =H15/(1-0.4)*2 -> 40262.633 | J15: =I15*(1-0.5) -> 20131.317 | L15: =$D$128 -> 598.53 | M15: 763.02 | N15: 344.25 | O15: =D104 -> 4377.03 | P15: 392.03 | Q15: =M78 -> 8841.36 | R15: =M78 -> 8841.36
B16: LS / LS | C16: ="No Lights - "&B16 -> No Lights - LS / LS | D16: 2 | E16: 0 | F16: No | G16: =SUM(L16:AA16) -> 46018.37 | H16: =G16*0.5 -> 23009.185 | I16: =H16/(1-0.4)*2 -> 76697.283 | J16: =I16*(1-0.5) -> 38348.642 | L16: =$D$128 -> 598.53 | M16: 763.02 | N16: 344.25 | O16: =D101 -> 7014.03 | P16: 0 | Q16: =M80 -> 18649.27 | R16: =M80 -> 18649.27
B17: FP / LS | C17: ="No Lights - "&B17 -> No Lights - FP / LS | D17: 2 | E17: 0 | F17: No | G17: =SUM(L17:AA17) -> 33986.55 | H17: =G17*0.5 -> 16993.275 | I17: =H17/(1-0.4)*2 -> 56644.25 | J17: =I17*(1-0.5) -> 28322.125 | L17: =$D$128 -> 598.53 | M17: 763.02 | N17: 344.25 | O17: =D102 -> 4790.12 | P17: 0 | Q17: =M78 -> 8841.36 | R17: =M80 -> 18649.27
B18: LS / FP | C18: ="No Lights - "&B18 -> No Lights - LS / FP | D18: 2 | E18: 0 | F18: No | G18: =SUM(L18:AA18) -> 23412.07 | H18: =G18*0.5 -> 11706.035 | I18: =H18/(1-0.4)*2 -> 39020.117 | J18: =I18*(1-0.5) -> 19510.058 | L18: =$D$128 -> 598.53 | M18: 763.02 | N18: 344.25 | O18: =D103 -> 4622.88 | P18: 392.03 | Q18: =M79 -> 7850 | R18: =M78 -> 8841.36
